Workbook

Sheet Output BDV
F3: =+SUM(F5:F1000) -> 9.4862799e-08 | G3: =+SUM(G5:G1000) -> 6 | H3: =+SUM(H5:H1000) -> 6.0000002 | M3: 673226.64
A4: SP/CE | B4: ricavi o costi | C4: Ricla MG esteso | D4: Key | E4: Account | F4: CVS | G4: De Giorgi | H4: Total
A5: SP | C5: Intangible Assets | D5: =+_xlfn.NUMBERVALUE(LEFT(E5,6)) -> 100201 | E5: 100201 - Costi Di Impianto E Ampliamento | F5: =+_xlfn.XLOOKUP(D5,CVS!E:E,CVS!I:I,0) -> 4214.29 | G5: =+SUMIFS('De Giorgi BDV'!C:C,'De Giorgi BDV'!D:D,D5) -> 0 | H5: =+F5+G5 -> 4214.29 | I5: =+_xlfn.XLOOKUP(D5,[1]BDV!$F:$F,[1]BDV!$AI:$AI) -> 4214.29 | J5: =+H5-I5 -> 0
A6: SP | B6: 0 | C6: Intangible Assets | D6: =+_xlfn.NUMBERVALUE(LEFT(E6,6)) -> 100203 | E6: 100203 - Software | F6: =+_xlfn.XLOOKUP(D6,CVS!E:E,CVS!I:I,0) -> 4758632.6 | G6: =+SUMIFS('De Giorgi BDV'!C:C,'De Giorgi BDV'!D:D,D6) -> 33076 | H6: =+F6+G6 -> 4791708.6 | I6: =+_xlfn.XLOOKUP(D6,[1]BDV!$F:$F,[1]BDV!$AI:$AI) -> 4791708.6 | J6: =+H6-I6 -> 0
A7: SP | B7: 0 | C7: Intangible Assets | D7: =+_xlfn.NUMBERVALUE(LEFT(E7,6)) -> 100205 | E7: 100205 - Avviamento | F7: =+_xlfn.XLOOKUP(D7,CVS!E:E,CVS!I:I,0) -> 50053945 | G7: =+SUMIFS('De Giorgi BDV'!C:C,'De Giorgi BDV'!D:D,D7) -> 0 | H7: =+F7+G7 -> 50053945 | I7: =+_xlfn.XLOOKUP(D7,[1]BDV!$F:$F,[1]BDV!$AI:$AI) -> 50053945 | J7: =+H7-I7 -> 0
A8: SP | B8: 0 | C8: Intangible Assets | D8: =+_xlfn.NUMBERVALUE(LEFT(E8,6)) -> 100207 | E8: 100207 - Lavori Straor. Su Beni Di Terzi | F8: =+_xlfn.XLOOKUP(D8,CVS!E:E,CVS!I:I,0) -> 1.2097657e+08 | G8: =+SUMIFS('De Giorgi BDV'!C:C,'De Giorgi BDV'!D:D,D8) -> 1044800.9 | H8: =+F8+G8 -> 1.2202137e+08 | I8: =+_xlfn.XLOOKUP(D8,[1]BDV!$F:$F,[1]BDV!$AI:$AI) -> 1.2202137e+08 | J8: =+H8-I8 -> 0
A9: SP | B9: 0 | C9: Intangible Assets | D9: =+_xlfn.NUMBERVALUE(LEFT(E9,6)) -> 100209 | E9: 100209 - Lavori Straor. Su Beni Di Terzi In Corso | F9: =+_xlfn.XLOOKUP(D9,CVS!E:E,CVS!I:I,0) -> 21620273 | G9: =+SUMIFS('De Giorgi BDV'!C:C,'De Giorgi BDV'!D:D,D9) -> 0 | H9: =+F9+G9 -> 21620273 | I9: =+_xlfn.XLOOKUP(D9,[1]BDV!$F:$F,[1]BDV!$AI:$AI) -> 21620273 | J9: =+H9-I9 -> 0
A10: SP | B10: 0 | C10: Intangible Assets | D10: =+_xlfn.NUMBERVALUE(LEFT(E10,6)) -> 100215 | E10: 100215 - Concessioni, Licenze E Marchi | F10: =+_xlfn.XLOOKUP(D10,CVS!E:E,CVS!I:I,0) -> 354977.91 | G10: =+SUMIFS('De Giorgi BDV'!C:C,'De Giorgi BDV'!D:D,D10) -> 0 | H10: =+F10+G10 -> 354977.91 | I10: =+_xlfn.XLOOKUP(D10,[1]BDV!$F:$F,[1]BDV!$AI:$AI) -> 354977.91 | J10: =+H10-I10 -> 0
A11: SP | B11: 0 | C11: Intangible Assets | D11: =+_xlfn.NUMBERVALUE(LEFT(E11,6)) -> 100217 | E11: 100217 - Altri Costi Ad Util. Plur. Da Amm. | F11: =+_xlfn.XLOOKUP(D11,CVS!E:E,CVS!I:I,0) -> 201871.57 | G11: =+SUMIFS('De Giorgi BDV'!C:C,'De Giorgi BDV'!D:D,D11) -> 8966.25 | H11: =+F11+G11 -> 210837.82 | I11: =+_xlfn.XLOOKUP(D11,[1]BDV!$F:$F,[1]BDV!$AI:$AI) -> 210837.82 | J11: =+H11-I11 -> 0
A12: SP | B12: 0 | C12: Intangible Assets | D12: =+_xlfn.NUMBERVALUE(LEFT(E12,6)) -> 100223 | E12: 100223 - F/Amm. Costi Impianto | F12: =+_xlfn.XLOOKUP(D12,CVS!E:E,CVS!I:I,0) -> -1496.05 | G12: =+SUMIFS('De Giorgi BDV'!C:C,'De Giorgi BDV'!D:D,D12) -> 0 | H12: =+F12+G12 -> -1496.05 | I12: =+_xlfn.XLOOKUP(D12,[1]BDV!$F:$F,[1]BDV!$AI:$AI) -> -1496.05 | J12: =+H12-I12 -> 0
A13: SP | B13: 0 | C13: Intangible Assets | D13: =+_xlfn.NUMBERVALUE(LEFT(E13,6)) -> 100225 | E13: 100225 - F/Amm Software | F13: =+_xlfn.XLOOKUP(D13,CVS!E:E,CVS!I:I,0) -> -2334868.1 | G13: =+SUMIFS('De Giorgi BDV'!C:C,'De Giorgi BDV'!D:D,D13) -> -33076 | H13: =+F13+G13 -> -2367944.1 | I13: =+_xlfn.XLOOKUP(D13,[1]BDV!$F:$F,[1]BDV!$AI:$AI) -> -2367944.1 | J13: =+H13-I13 -> 0
A14: SP | B14: 0 | C14: Intangible Assets | D14: =+_xlfn.NUMBERVALUE(LEFT(E14,6)) -> 100227 | E14: 100227 - F/Amm Avviamento | F14: =+_xlfn.XLOOKUP(D14,CVS!E:E,CVS!I:I,0) -> -8392.14 | G14: =+SUMIFS('De Giorgi BDV'!C:C,'De Giorgi BDV'!D:D,D14) -> 0 | H14: =+F14+G14 -> -8392.14 | I14: =+_xlfn.XLOOKUP(D14,[1]BDV!$F:$F,[1]BDV!$AI:$AI) -> -8392.14 | J14: =+H14-I14 -> 0
A15: SP | B15: 0 | C15: Intangible Assets | D15: =+_xlfn.NUMBERVALUE(LEFT(E15,6)) -> 100231 | E15: 100231 - F/Amm Concessioni, Licenze E Marchi | F15: =+_xlfn.XLOOKUP(D15,CVS!E:E,CVS!I:I,0) -> -260807.85 | G15: =+SUMIFS('De Giorgi BDV'!C:C,'De Giorgi BDV'!D:D,D15) -> 0 | H15: =+F15+G15 -> -260807.85 | I15: =+_xlfn.XLOOKUP(D15,[1]BDV!$F:$F,[1]BDV!$AI:$AI) -> -260807.85 | J15: =+H15-I15 -> 0
A16: SP | B16: 0 | C16: Intangible Assets | D16: =+_xlfn.NUMBERVALUE(LEFT(E16,6)) -> 100235 | E16: 100235 - F/Amm. Lav. Str. Su Beni Di Terzi | F16: =+_xlfn.XLOOKUP(D16,CVS!E:E,CVS!I:I,0) -> -43002348 | G16: =+SUMIFS('De Giorgi BDV'!C:C,'De Giorgi BDV'!D:D,D16) -> -466034.54 | H16: =+F16+G16 -> -43468383 | I16: =+_xlfn.XLOOKUP(D16,[1]BDV!$F:$F,[1]BDV!$AI:$AI) -> -43468383 | J16: =+H16-I16 -> 0
A17: SP | B17: 0 | C17: Intangible Assets | D17: =+_xlfn.NUMBERVALUE(LEFT(E17,6)) -> 100237 | E17: 100237 - F/Amm. Alt. Cost. Ad Ut. Plu. Amm. | F17: =+_xlfn.XLOOKUP(D17,CVS!E:E,CVS!I:I,0) -> -196064.56 | G17: =+SUMIFS('De Giorgi BDV'!C:C,'De Giorgi BDV'!D:D,D17) -> -8966.25 | H17: =+F17+G17 -> -205030.81 | I17: =+_xlfn.XLOOKUP(D17,[1]BDV!$F:$F,[1]BDV!$AI:$AI) -> -205030.81 | J17: =+H17-I17 -> 0
... A49: SP | B49: 0 | C49: Tangible Assets | D49: =+_xlfn.NUMBERVALUE(LEFT(E49,6)) -> 100455 | E49: 100455 - F/Amm Arredamento | F49: =+_xlfn.XLOOKUP(D49,CVS!E:E,CVS!I:I,0) -> -6367.3 | G49: =+SUMIFS('De Giorgi BDV'!C:C,'De Giorgi BDV'!D:D,D49) -> -24502.75 | H49: =+F49+G49 -> -30870.05 | I49: =+_xlfn.XLOOKUP(D49,[1]BDV!$F:$F,[1]BDV!$AI:$AI) -> -30870.05 | J49: =+H49-I49 -> 0
A50: SP | B50: FV | C50: Tangible Assets | D50: =+_xlfn.NUMBERVALUE(LEFT(E50,6)) -> 100457 | E50: 100457 - Immobiliazioni Materiali In Corso - FV Lizzano | F50: =+_xlfn.XLOOKUP(D50,CVS!E:E,CVS!I:I,0) -> 81349.91 | G50: =+SUMIFS('De Giorgi BDV'!C:C,'De Giorgi BDV'!D:D,D50) -> 0 | H50: =+F50+G50 -> 81349.91 | I50: =+_xlfn.XLOOKUP(D50,[1]BDV!$F:$F,[1]BDV!$AI:$AI) -> 81349.91 | J50: =+H50-I50 -> 0
A51: SP | B51: FV | C51: Tangible Assets | D51: =+_xlfn.NUMBERVALUE(LEFT(E51,6)) -> 100459 | E51: 100459 - Fornitori Imm. Materiali c/acconti - FV Mucca Nera | F51: =+_xlfn.XLOOKUP(D51,CVS!E:E,CVS!I:I,0) -> 5035.95 | G51: =+SUMIFS('De Giorgi BDV'!C:C,'De Giorgi BDV'!D:D,D51) -> 0 | H51: =+F51+G51 -> 5035.95 | I51: =+_xlfn.XLOOKUP(D51,[1]BDV!$F:$F,[1]BDV!$AI:$AI) -> 5035.95 | J51: =+H51-I51 -> 0
A52: SP | B52: 0 | C52: Tangible Assets | D52: =+_xlfn.NUMBERVALUE(LEFT(E52,6)) -> 100461 | E52: 100461 - Fornitori Imm. Materiali c/acconti | F52: =+_xlfn.XLOOKUP(D52,CVS!E:E,CVS!I:I,0) -> 46863.2 | G52: =+SUMIFS('De Giorgi BDV'!C:C,'De Giorgi BDV'!D:D,D52) -> 0 | H52: =+F52+G52 -> 46863.2 | I52: =+_xlfn.XLOOKUP(D52,[1]BDV!$F:$F,[1]BDV!$AI:$AI) -> 46863.2 | J52: =+H52-I52 -> 0
A53: SP | B53: 0 | C53: Tangible Assets | D53: =+_xlfn.NUMBERVALUE(LEFT(E53,6)) -> 100463 | E53: 100463 - Fabbricati Ind.Li e Comm. Li (MiniPia) | F53: =+_xlfn.XLOOKUP(D53,CVS!E:E,CVS!I:I,0) -> 542422.65 | G53: =+SUMIFS('De Giorgi BDV'!C:C,'De Giorgi BDV'!D:D,D53) -> 0 | H53: =+F53+G53 -> 542422.65 | I53: =+_xlfn.XLOOKUP(D53,[1]BDV!$F:$F,[1]BDV!$AI:$AI) -> 542422.65 | J53: =+H53-I53 -> 0
A54: SP | B54: 0 | C54: Tangible Assets | D54: =+_xlfn.NUMBERVALUE(LEFT(E54,6)) -> 100465 | E54: 100465 - F/Amm Fabbricati Ind.Li E Comm. Li (MiniPia) | F54: =+_xlfn.XLOOKUP(D54,CVS!E:E,CVS!I:I,0) -> -59135.35 | G54: =+SUMIFS('De Giorgi BDV'!C:C,'De Giorgi BDV'!D:D,D54) -> 0 | H54: =+F54+G54 -> -59135.35 | I54: =+_xlfn.XLOOKUP(D54,[1]BDV!$F:$F,[1]BDV!$AI:$AI) -> -59135.35 | J54: =+H54-I54 -> 0
A55: SP | B55: 0 | C55: Tangible Assets | D55: =+_xlfn.NUMBERVALUE(LEFT(E55,6)) -> 100467 | E55: 100467 - F/Amm. Beni Inferiori Ai 516,46 Euro | F55: =+_xlfn.XLOOKUP(D55,CVS!E:E,CVS!I:I,0) -> -18097.31 | G55: =+SUMIFS('De Giorgi BDV'!C:C,'De Giorgi BDV'!D:D,D55) -> 0 | H55: =+F55+G55 -> -18097.31 | I55: =+_xlfn.XLOOKUP(D55,[1]BDV!$F:$F,[1]BDV!$AI:$AI) -> -18097.31 | J55: =+H55-I55 -> 0
A56: SP | B56: FV | C56: Tangible Assets | D56: =+_xlfn.NUMBERVALUE(LEFT(E56,6)) -> 100469 | E56: 100469 - Immobiliazioni Materiali In Corso - FV Avezzano 3 | F56: =+_xlfn.XLOOKUP(D56,CVS!E:E,CVS!I:I,0) -> 1164176.8 | G56: =+SUMIFS('De Giorgi BDV'!C:C,'De Giorgi BDV'!D:D,D56) -> 0 | H56: =+F56+G56 -> 1164176.8 | I56: =+_xlfn.XLOOKUP(D56,[1]BDV!$F:$F,[1]BDV!$AI:$AI) -> 1164176.8 | J56: =+H56-I56 -> 0
A57: SP | B57: FV | C57: Tangible Assets | D57: =+_xlfn.NUMBERVALUE(LEFT(E57,6)) -> 100471 | E57: 100471 - Immobiliazioni Materiali In Corso - FV Montorio al Vomano 1 | F57: =+_xlfn.XLOOKUP(D57,CVS!E:E,CVS!I:I,0) -> 1645137.9 | G57: =+SUMIFS('De Giorgi BDV'!C:C,'De Giorgi BDV'!D:D,D57) -> 0 | H57: =+F57+G57 -> 1645137.9 | I57: =+_xlfn.XLOOKUP(D57,[1]BDV!$F:$F,[1]BDV!$AI:$AI) -> 1645137.9 | J57: =+H57-I57 -> 0
A58: SP | B58: FV | C58: Tangible Assets | D58: =+_xlfn.NUMBERVALUE(LEFT(E58,6)) -> 100473 | E58: 100473 - Immobiliazioni Materiali In Corso - FV Giulianova | F58: =+_xlfn.XLOOKUP(D58,CVS!E:E,CVS!I:I,0) -> 921393.76 | G58: =+SUMIFS('De Giorgi BDV'!C:C,'De Giorgi BDV'!D:D,D58) -> 0 | H58: =+F58+G58 -> 921393.76 | I58: =+_xlfn.XLOOKUP(D58,[1]BDV!$F:$F,[1]BDV!$AI:$AI) -> 921393.76 | J58: =+H58-I58 -> 0
A59: SP | B59: FV | C59: Tangible Assets | D59: =+_xlfn.NUMBERVALUE(LEFT(E59,6)) -> 100475 | E59: 100475 - Immobiliazioni Materiali In Corso - FV Borgorose | F59: =+_xlfn.XLOOKUP(D59,CVS!E:E,CVS!I:I,0) -> 973496.14 | G59: =+SUMIFS('De Giorgi BDV'!C:C,'De Giorgi BDV'!D:D,D59) -> 0 | H59: =+F59+G59 -> 973496.14 | I59: =+_xlfn.XLOOKUP(D59,[1]BDV!$F:$F,[1]BDV!$AI:$AI) -> 973496.14 | J59: =+H59-I59 -> 0
A60: SP | B60: FV | C60: Tangible Assets | D60: =+_xlfn.NUMBERVALUE(LEFT(E60,6)) -> 100477 | E60: 100477 - Immobiliazioni Materiali In Corso - FV Copertino 1 | F60: =+_xlfn.XLOOKUP(D60,CVS!E:E,CVS!I:I,0) -> 1115669.6 | G60: =+SUMIFS('De Giorgi BDV'!C:C,'De Giorgi BDV'!D:D,D60) -> 0 | H60: =+F60+G60 -> 1115669.6 | I60: =+_xlfn.XLOOKUP(D60,[1]BDV!$F:$F,[1]BDV!$AI:$AI) -> 1115669.6 | J60: =+H60-I60 -> 0
A61: SP | B61: FV | C61: Tangible Assets | D61: =+_xlfn.NUMBERVALUE(LEFT(E61,6)) -> 100479 | E61: 100479 - Immobiliazioni Materiali In Corso - FV Corfinio | F61: =+_xlfn.XLOOKUP(D61,CVS!E:E,CVS!I:I,0) -> 829090.49 | G61: =+SUMIFS('De Giorgi BDV'!C:C,'De Giorgi BDV'!D:D,D61) -> 0 | H61: =+F61+G61 -> 829090.49 | I61: =+_xlfn.XLOOKUP(D61,[1]BDV!$F:$F,[1]BDV!$AI:$AI) -> 829090.49 | J61: =+H61-I61 -> 0
A62: SP | B62: FV | C62: Tangible Assets | D62: =+_xlfn.NUMBERVALUE(LEFT(E62,6)) -> 100481 | E62: 100481 - Immobiliazioni Materiali In Corso - FV Avezzano 4 | F62: =+_xlfn.XLOOKUP(D62,CVS!E:E,CVS!I:I,0) -> 1087160.8 | G62: =+SUMIFS('De Giorgi BDV'!C:C,'De Giorgi BDV'!D:D,D62) -> 0 | H62: =+F62+G62 -> 1087160.8 | I62: =+_xlfn.XLOOKUP(D62,[1]BDV!$F:$F,[1]BDV!$AI:$AI) -> 1087160.8 | J62: =+H62-I62 -> 0
A63: SP | B63: FV | C63: Tangible Assets | D63: =+_xlfn.NUMBERVALUE(LEFT(E63,6)) -> 100483 | E63: 100483 - Immobiliazioni Materiali In Corso - FV Montorio al Vomano 3 | F63: =+_xlfn.XLOOKUP(D63,CVS!E:E,CVS!I:I,0) -> 991956.75 | G63: =+SUMIFS('De Giorgi BDV'!C:C,'De Giorgi BDV'!D:D,D63) -> 0 | H63: =+F63+G63 -> 991956.75 | I63: =+_xlfn.XLOOKUP(D63,[1]BDV!$F:$F,[1]BDV!$AI:$AI) -> 991956.75 | J63: =+H63-I63 -> 0
A64: SP | B64: FV | C64: Tangible Assets | D64: =+_xlfn.NUMBERVALUE(LEFT(E64,6)) -> 100485 | E64: 100485 - Immobiliazioni Materiali In Corso - FV Montorio al Vomano 4 | F64: =+_xlfn.XLOOKUP(D64,CVS!E:E,CVS!I:I,0) -> 916403.37 | G64: =+SUMIFS('De Giorgi BDV'!C:C,'De Giorgi BDV'!D:D,D64) -> 0 | H64: =+F64+G64 -> 916403.37 | I64: =+_xlfn.XLOOKUP(D64,[1]BDV!$F:$F,[1]BDV!$AI:$AI) -> 916403.37 | J64: =+H64-I64 -> 0
A65: SP | B65: FV | C65: Tangible Assets | D65: =+_xlfn.NUMBERVALUE(LEFT(E65,6)) -> 100487 | E65: 100487 - Immobiliazioni Materiali In Corso - FV Collarmele | F65: =+_xlfn.XLOOKUP(D65,CVS!E:E,CVS!I:I,0) -> 838538.06 | G65: =+SUMIFS('De Giorgi BDV'!C:C,'De Giorgi BDV'!D:D,D65) -> 0 | H65: =+F65+G65 -> 838538.06 | I65: =+_xlfn.XLOOKUP(D65,[1]BDV!$F:$F,[1]BDV!$AI:$AI) -> 838538.06 | J65: =+H65-I65 -> 0
A66: SP | B66: FV | C66: Tangible Assets | D66: =+_xlfn.NUMBERVALUE(LEFT(E66,6)) -> 100489 | E66: 100489 - Immobiliazioni Materiali In Corso - FV Campi Salentina 1 | F66: =+_xlfn.XLOOKUP(D66,CVS!E:E,CVS!I:I,0) -> 1087448.5 | G66: =+SUMIFS('De Giorgi BDV'!C:C,'De Giorgi BDV'!D:D,D66) -> 0 | H66: =+F66+G66 -> 1087448.5 | I66: =+_xlfn.XLOOKUP(D66,[1]BDV!$F:$F,[1]BDV!$AI:$AI) -> 1087448.5 | J66: =+H66-I66 -> 0
A67: SP | B67: FV | C67: Tangible Assets | D67: =+_xlfn.NUMBERVALUE(LEFT(E67,6)) -> 100491 | E67: 100491 - Immobiliazioni Materiali In Corso - FV Copertino 2 | F67: =+_xlfn.XLOOKUP(D67,CVS!E:E,CVS!I:I,0) -> 766621.33 | G67: =+SUMIFS('De Giorgi BDV'!C:C,'De Giorgi BDV'!D:D,D67) -> 0 | H67: =+F67+G67 -> 766621.33 | I67: =+_xlfn.XLOOKUP(D67,[1]BDV!$F:$F,[1]BDV!$AI:$AI) -> 766621.33 | J67: =+H67-I67 -> 0
... A71: SP | B71: FV | C71: Tangible Assets | D71: =+_xlfn.NUMBERVALUE(LEFT(E71,6)) -> 100499 | E71: 100499 - Immobiliazioni Materiali In Corso - FV Tricase | F71: =+_xlfn.XLOOKUP(D71,CVS!E:E,CVS!I:I,0) -> 143607.9 | G71: =+SUMIFS('De Giorgi BDV'!C:C,'De Giorgi BDV'!D:D,D71) -> 0 | H71: =+F71+G71 -> 143607.9 | I71: =+_xlfn.XLOOKUP(D71,[1]BDV!$F:$F,[1]BDV!$AI:$AI) -> 143607.9 | J71: =+H71-I71 -> 0
A72: SP | B72: 0 | C72: Intangible Assets | D72: =+_xlfn.NUMBERVALUE(LEFT(E72,6)) -> 100501 | E72: 100501 - Diritti D'uso | F72: =+_xlfn.XLOOKUP(D72,CVS!E:E,CVS!I:I,0) -> 3399355.5 | G72: =+SUMIFS('De Giorgi BDV'!C:C,'De Giorgi BDV'!D:D,D72) -> 0 | H72: =+F72+G72 -> 3399355.5 | I72: =+_xlfn.XLOOKUP(D72,[1]BDV!$F:$F,[1]BDV!$AI:$AI) -> 3399355.5 | J72: =+H72-I72 -> 0
A73: SP | B73: 0 | C73: Intangible Assets | D73: =+_xlfn.NUMBERVALUE(LEFT(E73,6)) -> 100503 | E73: 100503 - Fondo amm.to diritti d'uso | F73: =+_xlfn.XLOOKUP(D73,CVS!E:E,CVS!I:I,0) -> -1302951.5 | G73: =+SUMIFS('De Giorgi BDV'!C:C,'De Giorgi BDV'!D:D,D73) -> 0 | H73: =+F73+G73 -> -1302951.5 | I73: =+_xlfn.XLOOKUP(D73,[1]BDV!$F:$F,[1]BDV!$AI:$AI) -> -1302951.5 | J73: =+H73-I73 -> 0
A74: SP | B74: FV | C74: Tangible Assets | D74: =+_xlfn.NUMBERVALUE(LEFT(E74,6)) -> 100505 | E74: 100505 - Immobiliazioni Materiali In Corso - FV San Giorgio Ionico | F74: =+_xlfn.XLOOKUP(D74,CVS!E:E,CVS!I:I,0) -> 154101.24 | G74: =+SUMIFS('De Giorgi BDV'!C:C,'De Giorgi BDV'!D:D,D74) -> 0 | H74: =+F74+G74 -> 154101.24 | I74: =+_xlfn.XLOOKUP(D74,[1]BDV!$F:$F,[1]BDV!$AI:$AI) -> 154101.24 | J74: =+H74-I74 -> 0
A75: SP | B75: FV | C75: Tangible Assets | D75: =+_xlfn.NUMBERVALUE(LEFT(E75,6)) -> 100509 | E75: 100509 - Immobiliazioni Materiali In Corso - FV Avezzano 5 | F75: =+_xlfn.XLOOKUP(D75,CVS!E:E,CVS!I:I,0) -> 57320.6 | G75: =+SUMIFS('De Giorgi BDV'!C:C,'De Giorgi BDV'!D:D,D75) -> 0 | H75: =+F75+G75 -> 57320.6 | I75: =+_xlfn.XLOOKUP(D75,[1]BDV!$F:$F,[1]BDV!$AI:$AI) -> 57320.6 | J75: =+H75-I75 -> 0
A76: SP | B76: FV | C76: Tangible Assets | D76: =+_xlfn.NUMBERVALUE(LEFT(E76,6)) -> 100513 | E76: 100513 - Immobiliazioni Materiali In Corso - FV Taviano 2 | F76: =+_xlfn.XLOOKUP(D76,CVS!E:E,CVS!I:I,0) -> 411699.71 | G76: =+SUMIFS('De Giorgi BDV'!C:C,'De Giorgi BDV'!D:D,D76) -> 0 | H76: =+F76+G76 -> 411699.71 | I76: =+_xlfn.XLOOKUP(D76,[1]BDV!$F:$F,[1]BDV!$AI:$AI) -> 411699.71 | J76: =+H76-I76 -> 0
...

Sheet De Giorgi BDV
B1: ATTIVO | C1: =SUBTOTAL(9,C9:C38) -> 2709096.5
B2: PASSIVO | C2: =SUBTOTAL(9,C41:C71) -> -2676155.7 | E2: RISULTATO DI ESERCIZIO | F2: =+C1+C2 -> 32940.77
B3: COSTI | C3: =SUBTOTAL(9,C74:C149) -> 787941.81
B4: RICAVI | C4: =SUBTOTAL(9,C152:C163) -> -820882.58
A5: De Giorgi | D5: Civismart
A6: Codice | B6: Descrizione | C6: Saldo al 31/12/2026 | D6: Codice | E6: Type | F6: Descrizione | G6: Note
A8: ** | B8: ATTIVO
A9: 03/15/015 | B9: LIC.ZA USO SOFTWARE TEMPO INDET. | C9: 33076 | D9: 100203 | E9: Fixed Asset | F9: Software | H9: =+_xlfn.XLOOKUP(D9,'Output BDV'!D:D,'Output BDV'!D:D) -> 100203
A10: 03/35/005 | B10: LAVORI STRAOR. SU BENI DI TERZI | C10: 159664.19 | D10: 100207 | E10: Fixed Asset | F10: Lavori Straor. Su Beni Di Terzi | H10: =+_xlfn.XLOOKUP(D10,'Output BDV'!D:D,'Output BDV'!D:D) -> 100207
A11: 03/35/015 | B11: ALTRI COSTI AD UTIL.PLUR.DA AMM. | C11: 8966.25 | D11: 100217 | E11: Fixed Asset | F11: Altri Costi Ad Util. Plur. Da Amm. | H11: =+_xlfn.XLOOKUP(D11,'Output BDV'!D:D,'Output BDV'!D:D) -> 100217
A12: 03/35/501 | B12: COSTI APPALTO LIZZANELLO | C12: 885136.76 | D12: 100207 | E12: Fixed Asset | F12: Lavori Straor. Su Beni Di Terzi | H12: =+_xlfn.XLOOKUP(D12,'Output BDV'!D:D,'Output BDV'!D:D) -> 100207
A13: 06/05/005 | B13: TERRENI | C13: 11857.65 | D13: 100401 | E13: Fixed Asset | F13: Terreni | H13: =+_xlfn.XLOOKUP(D13,'Output BDV'!D:D,'Output BDV'!D:D) -> 100401
A14: 06/05/015 | B14: FABBRICATI IND.LI E COMM.LI | C14: 385661.11 | D14: 100405 | E14: Fixed Asset | F14: Fabbricati Ind.Li E Comm. Li | H14: =+_xlfn.XLOOKUP(D14,'Output BDV'!D:D,'Output BDV'!D:D) -> 100405
A15: 06/10/005 | B15: IMPIANTI GENERICI | C15: 4098.25 | D15: 100415 | E15: Fixed Asset | F15: Impianti Generici | H15: =+_xlfn.XLOOKUP(D15,'Output BDV'!D:D,'Output BDV'!D:D) -> 100415
A16: 06/10/015 | B16: MACCHINARI | C16: 32895.58 | D16: 100409 | E16: Fixed Asset | F16: Macchinari | H16: =+_xlfn.XLOOKUP(D16,'Output BDV'!D:D,'Output BDV'!D:D) -> 100409
A17: 06/15/005 | B17: ATTREZZAT. IND.LI E COMM.LI | C17: 41352.67 | D17: 100411 | E17: Fixed Asset | F17: Attrezzature Industriali E Commerciali | H17: =+_xlfn.XLOOKUP(D17,'Output BDV'!D:D,'Output BDV'!D:D) -> 100411
A18: 06/15/010 | B18: ATTR.VARIE E MINUTE (<516,46 E.) | C18: 40456.09 | D18: 100413 | E18: Fixed Asset | F18: Attrezzatura Varia E Minuta | H18: =+_xlfn.XLOOKUP(D18,'Output BDV'!D:D,'Output BDV'!D:D) -> 100413
A19: 06/20/010 | B19: MACCHINE ELETTROMEC. D'UFFICIO | C19: 18720.07 | D19: 100421 | E19: Fixed Asset | F19: Macchine Elettromeccaniche D'ufficio | H19: =+_xlfn.XLOOKUP(D19,'Output BDV'!D:D,'Output BDV'!D:D) -> 100421
A20: 06/25/015 | B20: AUTOCARRI/AUTOVETTURE | C20: 214006.57 | D20: 100423 | E20: Fixed Asset | F20: Autoveicoli E Autocarri | H20: =+_xlfn.XLOOKUP(D20,'Output BDV'!D:D,'Output BDV'!D:D) -> 100423
... A31: 18/25/020 | B31: INAIL C/ACCONTI | C31: 6119.97 | D31: 160413 | E31: Other Current Asset | F31: I.N.A.I.L. C/Acconti | H31: =+_xlfn.XLOOKUP(D31,'Output BDV'!D:D,'Output BDV'!D:D) -> 160413
A32: 24/05/002 | B32: BANCA MPS C/C 1616312 | C32: 172828.39 | D32: 24/05/002 | G32: Da creare | H32: =+_xlfn.XLOOKUP(D32,'Output BDV'!D:D,'Output BDV'!D:D) -> 24/05/002
A33: 24/05/003 | B33: BANCA INTESA - EX B.NAPOLI | C33: 121605.94 | D33: 24/05/003 | G33: Da creare | H33: =+_xlfn.XLOOKUP(D33,'Output BDV'!D:D,'Output BDV'!D:D) -> 24/05/003
A34: 24/05/006 | B34: CARTA PREPAGATA INTESA 50 | C34: 56.06 | D34: 24/05/006 | G34: Da creare | H34: =+_xlfn.XLOOKUP(D34,'Output BDV'!D:D,'Output BDV'!D:D) -> 24/05/006
A35: 24/15/005 | B35: DENARO IN CASSA | C35: 6.87 | D35: 180201 | E35: Bank | F35: Cassa | H35: =+_xlfn.XLOOKUP(D35,'Output BDV'!D:D,'Output BDV'!D:D) -> 180201
A36: 26/10/005 | B36: RISCONTI ATTIVI | C36: 5531.99 | D36: 360201 | E36: Deferred Expense | F36: Risconti Attivi | H36: =+_xlfn.XLOOKUP(D36,'Output BDV'!D:D,'Output BDV'!D:D) -> 360201
A37: 48/05/040 | B37: ERARIO C/IVA | C37: 3253.16 | D37: 320409 | E37: Other Current Liability | F37: Erario C/Iva | H37: =+_xlfn.XLOOKUP(D37,'Output BDV'!D:D,'Output BDV'!D:D) -> 320409
A38: 48/05/100 | B38: REGIONI C/IRAP | C38: 4339 | D38: 320405 | E38: Other Current Liability | F38: Regioni C/Irap | H38: =+_xlfn.XLOOKUP(D38,'Output BDV'!D:D,'Output BDV'!D:D) -> 320405
H39: =+_xlfn.XLOOKUP(D39,'Output BDV'!D:D,'Output BDV'!D:D) -> 0
A40: ** | B40: PASSIVO | H40: =+_xlfn.XLOOKUP(D40,'Output BDV'!D:D,'Output BDV'!D:D) -> 0
A41: 04/15/015 | B41: F/AMM.LIC. D'USO SOF. A TEM. IND | C41: -33076 | D41: 100225 | E41: Fixed Asset | F41: F/Amm Software | H41: =+_xlfn.XLOOKUP(D41,'Output BDV'!D:D,'Output BDV'!D:D) -> 100225
A42: 04/35/005 | B42: F/AMM. LAV. STR. SU BENI DI TERZ | C42: -149012.63 | D42: 100235 | E42: Fixed Asset | F42: F/Amm. Lav. Str. Su Beni Di Terzi | H42: =+_xlfn.XLOOKUP(D42,'Output BDV'!D:D,'Output BDV'!D:D) -> 100235
A43: 04/35/015 | B43: F/AMM.ALT. COS. AD UT. PLU. AMM | C43: -8966.25 | D43: 100237 | E43: Fixed Asset | F43: F/Amm. Alt. Cost. Ad Ut. Plu. Amm. | H43: =+_xlfn.XLOOKUP(D43,'Output BDV'!D:D,'Output BDV'!D:D) -> 100237
A44: 04/35/501 | B44: F/AMM COSTI APPALTO LIZZANELLO | C44: -317021.91 | D44: 100235 | E44: Fixed Asset | F44: F/Amm. Lav. Str. Su Beni Di Terzi | H44: =+_xlfn.XLOOKUP(D44,'Output BDV'!D:D,'Output BDV'!D:D) -> 100235
A45: 07/05/006 | B45: F/AMM. TERRENI | C45: -11857.65 | D45: 100429 | E45: Fixed Asset | F45: F/Amm Fabbricati Ind.Li E Comm. Li | H45: =+_xlfn.XLOOKUP(D45,'Output BDV'!D:D,'Output BDV'!D:D) -> 100429
A46: 07/05/015 | B46: F/AMM.FABBR. IND.LI E COMM.LI. | C46: -221946.25 | D46: 100429 | E46: Fixed Asset | F46: F/Amm Fabbricati Ind.Li E Comm. Li | H46: =+_xlfn.XLOOKUP(D46,'Output BDV'!D:D,'Output BDV'!D:D) -> 100429
A47: 07/10/005 | B47: F/AMM.IMPIANTI GENERICI | C47: -3971.97 | D47: 100439 | E47: Fixed Asset | F47: F/Amm Impianti Generici | H47: =+_xlfn.XLOOKUP(D47,'Output BDV'!D:D,'Output BDV'!D:D) -> 100439
A48: 07/10/015 | B48: F/AMM.MACCHINARI | C48: -31725.72 | D48: 100433 | E48: Fixed Asset | F48: F/Amm Macchinari | H48: =+_xlfn.XLOOKUP(D48,'Output BDV'!D:D,'Output BDV'!D:D) -> 100433
A49: 07/15/005 | B49: F/AMM.ATTREZ. IND.LI E COMM.LI | C49: -41194.32 | D49: 100435 | E49: Fixed Asset | F49: F/Amm Attrezzatura Industriali E Commerciali | H49: =+_xlfn.XLOOKUP(D49,'Output BDV'!D:D,'Output BDV'!D:D) -> 100435
A50: 07/15/010 | B50: F/AMM.ATTR. VARIE E MINUTE | C50: -40456.09 | D50: 100437 | E50: Fixed Asset | F50: F/Amm Attrezzatura Varia E Minuta | H50: =+_xlfn.XLOOKUP(D50,'Output BDV'!D:D,'Output BDV'!D:D) -> 100437
A51: 07/20/010 | B51: F/AMM.MACCH. ELETTROM. D'UFF. | C51: -16375.74 | D51: 100445 | E51: Fixed Asset | F51: F/Amm Macchine Elettromeccaniche D'ufficio | H51: =+_xlfn.XLOOKUP(D51,'Output BDV'!D:D,'Output BDV'!D:D) -> 100445
...

Sheet CVS
B4: Quadro | C4: Altro | D4: Ricla MG esteso | E4: Conto | F4: Account | G4: Debit | H4: Credit | I4: Agosto | J4: Giugno | K4: Giu RR | L4: Delta
B5: SP | C5: 0 | D5: Intangible Assets | E5: =+_xlfn.NUMBERVALUE(LEFT(F5,6)) -> 100201 | F5: 100201 - Costi Di Impianto E Ampliamento | G5: 4214.29 | I5: =+G5-H5 -> 4214.29 | J5: =+_xlfn.XLOOKUP(E5,[1]BDV!$F:$F,[1]BDV!$AC:$AC) -> 4214.29 | K5: =+J5/6*8 -> 5619.0533 | L5: =+K5-I5 -> 1404.7633
B6: SP | C6: 0 | D6: Intangible Assets | E6: =+_xlfn.NUMBERVALUE(LEFT(F6,6)) -> 100203 | F6: 100203 - Software | G6: 4758632.6 | I6: =+G6-H6 -> 4758632.6 | J6: =+_xlfn.XLOOKUP(E6,[1]BDV!$F:$F,[1]BDV!$AC:$AC) -> 4717032.6 | K6: =+J6/6*8 -> 6289376.8 | L6: =+K6-I6 -> 1530744.2
B7: SP | C7: 0 | D7: Intangible Assets | E7: =+_xlfn.NUMBERVALUE(LEFT(F7,6)) -> 100205 | F7: 100205 - Avviamento | G7: 50053945 | I7: =+G7-H7 -> 50053945 | J7: =+_xlfn.XLOOKUP(E7,[1]BDV!$F:$F,[1]BDV!$AC:$AC) -> 50053945 | K7: =+J7/6*8 -> 66738593 | L7: =+K7-I7 -> 16684648
B8: SP | C8: 0 | D8: Intangible Assets | E8: =+_xlfn.NUMBERVALUE(LEFT(F8,6)) -> 100207 | F8: 100207 - Lavori Straor. Su Beni Di Terzi | G8: 1.2097657e+08 | I8: =+G8-H8 -> 1.2097657e+08 | J8: =+_xlfn.XLOOKUP(E8,[1]BDV!$F:$F,[1]BDV!$AC:$AC) -> 1.1670003e+08 | K8: =+J8/6*8 -> 1.5560004e+08 | L8: =+K8-I8 -> 34623468
B9: SP | C9: 0 | D9: Intangible Assets | E9: =+_xlfn.NUMBERVALUE(LEFT(F9,6)) -> 100209 | F9: 100209 - Lavori Straor. Su Beni Di Terzi In Corso | G9: 21620273 | I9: =+G9-H9 -> 21620273 | J9: =+_xlfn.XLOOKUP(E9,[1]BDV!$F:$F,[1]BDV!$AC:$AC) -> 20295752 | K9: =+J9/6*8 -> 27061002 | L9: =+K9-I9 -> 5440729.2
B10: SP | C10: 0 | D10: Intangible Assets | E10: =+_xlfn.NUMBERVALUE(LEFT(F10,6)) -> 100215 | F10: 100215 - Concessioni, Licenze E Marchi | G10: 354977.91 | I10: =+G10-H10 -> 354977.91 | J10: =+_xlfn.XLOOKUP(E10,[1]BDV!$F:$F,[1]BDV!$AC:$AC) -> 354977.91 | K10: =+J10/6*8 -> 473303.88 | L10: =+K10-I10 -> 118325.97
B11: SP | C11: 0 | D11: Intangible Assets | E11: =+_xlfn.NUMBERVALUE(LEFT(F11,6)) -> 100217 | F11: 100217 - Altri Costi Ad Util. Plur. Da Amm. | G11: 201871.57 | I11: =+G11-H11 -> 201871.57 | J11: =+_xlfn.XLOOKUP(E11,[1]BDV!$F:$F,[1]BDV!$AC:$AC) -> 201871.57 | K11: =+J11/6*8 -> 269162.09 | L11: =+K11-I11 -> 67290.523
B12: SP | C12: 0 | D12: Intangible Assets | E12: =+_xlfn.NUMBERVALUE(LEFT(F12,6)) -> 100223 | F12: 100223 - F/Amm. Costi Impianto | H12: 1496.05 | I12: =+G12-H12 -> -1496.05 | J12: =+_xlfn.XLOOKUP(E12,[1]BDV!$F:$F,[1]BDV!$AC:$AC) -> -1403.05 | K12: =+J12/6*8 -> -1870.7333 | L12: =+K12-I12 -> -374.68333
B13: SP | C13: 0 | D13: Intangible Assets | E13: =+_xlfn.NUMBERVALUE(LEFT(F13,6)) -> 100225 | F13: 100225 - F/Amm Software | H13: 2334868.1 | I13: =+G13-H13 -> -2334868.1 | J13: =+_xlfn.XLOOKUP(E13,[1]BDV!$F:$F,[1]BDV!$AC:$AC) -> -2176218.1 | K13: =+J13/6*8 -> -2901624.2 | L13: =+K13-I13 -> -566756.03
B14: SP | C14: 0 | D14: Intangible Assets | E14: =+_xlfn.NUMBERVALUE(LEFT(F14,6)) -> 100227 | F14: 100227 - F/Amm Avviamento | H14: 8392.14 | I14: =+G14-H14 -> -8392.14 | J14: =+_xlfn.XLOOKUP(E14,[1]BDV!$F:$F,[1]BDV!$AC:$AC) -> -8082.14 | K14: =+J14/6*8 -> -10776.187 | L14: =+K14-I14 -> -2384.0467
B15: SP | C15: 0 | D15: Intangible Assets | E15: =+_xlfn.NUMBERVALUE(LEFT(F15,6)) -> 100231 | F15: 100231 - F/Amm Concessioni, Licenze E Marchi | H15: 260807.85 | I15: =+G15-H15 -> -260807.85 | J15: =+_xlfn.XLOOKUP(E15,[1]BDV!$F:$F,[1]BDV!$AC:$AC) -> -253386.81 | K15: =+J15/6*8 -> -337849.08 | L15: =+K15-I15 -> -77041.23
B16: SP | C16: 0 | D16: Intangible Assets | E16: =+_xlfn.NUMBERVALUE(LEFT(F16,6)) -> 100235 | F16: 100235 - F/Amm. Lav. Str. Su Beni Di Terzi | H16: 43002348 | I16: =+G16-H16 -> -43002348 | J16: =+_xlfn.XLOOKUP(E16,[1]BDV!$F:$F,[1]BDV!$AC:$AC) -> -41630306 | K16: =+J16/6*8 -> -55507075 | L16: =+K16-I16 -> -12504727
B17: SP | C17: 0 | D17: Intangible Assets | E17: =+_xlfn.NUMBERVALUE(LEFT(F17,6)) -> 100237 | F17: 100237 - F/Amm. Alt. Cost. Ad Ut. Plu. Amm. | H17: 196064.56 | I17: =+G17-H17 -> -196064.56 | J17: =+_xlfn.XLOOKUP(E17,[1]BDV!$F:$F,[1]BDV!$AC:$AC) -> -195615.56 | K17: =+J17/6*8 -> -260820.75 | L17: =+K17-I17 -> -64756.187
B18: SP | C18: 0 | D18: Intangible Assets | E18: =+_xlfn.NUMBERVALUE(LEFT(F18,6)) -> 100239 | F18: 100239 - Spese Di Costituzione | G18: 55778.54 | I18: =+G18-H18 -> 55778.54 | J18: =+_xlfn.XLOOKUP(E18,[1]BDV!$F:$F,[1]BDV!$AC:$AC) -> 55778.54 | K18: =+J18/6*8 -> 74371.387 | L18: =+K18-I18 -> 18592.847
B19: SP | C19: 0 | D19: Intangible Assets | E19: =+_xlfn.NUMBERVALUE(LEFT(F19,6)) -> 100241 | F19: 100241 - F/Amm. Spese Di Costituzione | H19: 55414.19 | I19: =+G19-H19 -> -55414.19 | J19: =+_xlfn.XLOOKUP(E19,[1]BDV!$F:$F,[1]BDV!$AC:$AC) -> -55232.19 | K19: =+J19/6*8 -> -73642.92 | L19: =+K19-I19 -> -18228.73
B20: SP | C20: 0 | D20: Intangible Assets | E20: =+_xlfn.NUMBERVALUE(LEFT(F20,6)) -> 100249 | F20: 100249 - Lista clienti | G20: 29035481 | I20: =+G20-H20 -> 29035481 | J20: =+_xlfn.XLOOKUP(E20,[1]BDV!$F:$F,[1]BDV!$AC:$AC) -> 29035481 | K20: =+J20/6*8 -> 38713974 | L20: =+K20-I20 -> 9678493.5
B21: SP | C21: 0 | D21: Intangible Assets | E21: =+_xlfn.NUMBERVALUE(LEFT(F21,6)) -> 100251 | F21: 100251 - F.do amm.to Lista clienti | H21: 4531375.8 | I21: =+G21-H21 -> -4531375.8 | J21: =+_xlfn.XLOOKUP(E21,[1]BDV!$F:$F,[1]BDV!$AC:$AC) -> -4244018.4 | K21: =+J21/6*8 -> -5658691.2 | L21: =+K21-I21 -> -1127315.4
B22: SP | C22: 0 | D22: Tangible Assets | E22: =+_xlfn.NUMBERVALUE(LEFT(F22,6)) -> 100401 | F22: 100401 - Terreni | G22: 14238.97 | I22: =+G22-H22 -> 14238.97 | J22: =+_xlfn.XLOOKUP(E22,[1]BDV!$F:$F,[1]BDV!$AC:$AC) -> 106086.67 | K22: =+J22/6*8 -> 141448.89 | L22: =+K22-I22 -> 127209.92
B23: SP | C23: 0 | D23: Tangible Assets | E23: =+_xlfn.NUMBERVALUE(LEFT(F23,6)) -> 100403 | F23: 100403 - Beni Inferiori Ai 516,46 Euro | G23: 18097 | I23: =+G23-H23 -> 18097 | J23: =+_xlfn.XLOOKUP(E23,[1]BDV!$F:$F,[1]BDV!$AC:$AC) -> 18097 | K23: =+J23/6*8 -> 24129.333 | L23: =+K23-I23 -> 6032.3333
B24: SP | C24: 0 | D24: Tangible Assets | E24: =+_xlfn.NUMBERVALUE(LEFT(F24,6)) -> 100405 | F24: 100405 - Fabbricati Ind.Li E Comm. Li | G24: 1050820.4 | I24: =+G24-H24 -> 1050820.4 | J24: =+_xlfn.XLOOKUP(E24,[1]BDV!$F:$F,[1]BDV!$AC:$AC) -> 1050820.4 | K24: =+J24/6*8 -> 1401093.9 | L24: =+K24-I24 -> 350273.47
B25: SP | C25: 0 | D25: Tangible Assets | E25: =+_xlfn.NUMBERVALUE(LEFT(F25,6)) -> 100407 | F25: 100407 - Costruzioni Leggere | G25: 104546 | I25: =+G25-H25 -> 104546 | J25: =+_xlfn.XLOOKUP(E25,[1]BDV!$F:$F,[1]BDV!$AC:$AC) -> 104546 | K25: =+J25/6*8 -> 139394.67 | L25: =+K25-I25 -> 34848.667
B26: SP | C26: 0 | D26: Tangible Assets | E26: =+_xlfn.NUMBERVALUE(LEFT(F26,6)) -> 100409 | F26: 100409 - Macchinari | G26: 36920 | I26: =+G26-H26 -> 36920 | J26: =+_xlfn.XLOOKUP(E26,[1]BDV!$F:$F,[1]BDV!$AC:$AC) -> 36920 | K26: =+J26/6*8 -> 49226.667 | L26: =+K26-I26 -> 12306.667
B27: SP | C27: 0 | D27: Tangible Assets | E27: =+_xlfn.NUMBERVALUE(LEFT(F27,6)) -> 100411 | F27: 100411 - Attrezzature Industriali E Commerciali | G27: 717177.2 | I27: =+G27-H27 -> 717177.2 | J27: =+_xlfn.XLOOKUP(E27,[1]BDV!$F:$F,[1]BDV!$AC:$AC) -> 703528.86 | K27: =+J27/6*8 -> 938038.48 | L27: =+K27-I27 -> 220861.28
B28: SP | C28: 0 | D28: Tangible Assets | E28: =+_xlfn.NUMBERVALUE(LEFT(F28,6)) -> 100413 | F28: 100413 - Attrezzatura Varia E Minuta | G28: 77813.34 | I28: =+G28-H28 -> 77813.34 | J28: =+_xlfn.XLOOKUP(E28,[1]BDV!$F:$F,[1]BDV!$AC:$AC) -> 77813.34 | K28: =+J28/6*8 -> 103751.12 | L28: =+K28-I28 -> 25937.78
B29: SP | C29: 0 | D29: Tangible Assets | E29: =+_xlfn.NUMBERVALUE(LEFT(F29,6)) -> 100415 | F29: 100415 - Impianti Generici | G29: 372327.78 | I29: =+G29-H29 -> 372327.78 | J29: =+_xlfn.XLOOKUP(E29,[1]BDV!$F:$F,[1]BDV!$AC:$AC) -> 372327.78 | K29: =+J29/6*8 -> 496437.04 | L29: =+K29-I29 -> 124109.26
B30: SP | C30: 0 | D30: Tangible Assets | E30: =+_xlfn.NUMBERVALUE(LEFT(F30,6)) -> 100417 | F30: 100417 - Impianti Specifici | G30: 571065.7 | I30: =+G30-H30 -> 571065.7 | J30: =+_xlfn.XLOOKUP(E30,[1]BDV!$F:$F,[1]BDV!$AC:$AC) -> 571065.7 | K30: =+J30/6*8 -> 761420.93 | L30: =+K30-I30 -> 190355.23
B31: SP | C31: 0 | D31: Tangible Assets | E31: =+_xlfn.NUMBERVALUE(LEFT(F31,6)) -> 100419 | F31: 100419 - Mobili E Macchine Ordinarie D'ufficio | G31: 516770.12 | I31: =+G31-H31 -> 516770.12 | J31: =+_xlfn.XLOOKUP(E31,[1]BDV!$F:$F,[1]BDV!$AC:$AC) -> 513770.12 | K31: =+J31/6*8 -> 685026.83 | L31: =+K31-I31 -> 168256.71
B32: SP | C32: 0 | D32: Tangible Assets | E32: =+_xlfn.NUMBERVALUE(LEFT(F32,6)) -> 100421 | F32: 100421 - Macchine Elettromeccaniche D'ufficio | G32: 364211.72 | I32: =+G32-H32 -> 364211.72 | J32: =+_xlfn.XLOOKUP(E32,[1]BDV!$F:$F,[1]BDV!$AC:$AC) -> 348980.49 | K32: =+J32/6*8 -> 465307.32 | L32: =+K32-I32 -> 101095.6
B33: SP | C33: 0 | D33: Tangible Assets | E33: =+_xlfn.NUMBERVALUE(LEFT(F33,6)) -> 100423 | F33: 100423 - Autoveicoli E Autocarri | G33: 710845.27 | I33: =+G33-H33 -> 710845.27 | J33: =+_xlfn.XLOOKUP(E33,[1]BDV!$F:$F,[1]BDV!$AC:$AC) -> 710845.27 | K33: =+J33/6*8 -> 947793.69 | L33: =+K33-I33 -> 236948.42
... B35: SP | C35: 0 | D35: Tangible Assets | E35: =+_xlfn.NUMBERVALUE(LEFT(F35,6)) -> 100427 | F35: 100427 - Appar. Radiomobili Detr. 80% | G35: 46069.52 | I35: =+G35-H35 -> 46069.52 | J35: =+_xlfn.XLOOKUP(E35,[1]BDV!$F:$F,[1]BDV!$AC:$AC) -> 46069.52 | K35: =+J35/6*8 -> 61426.027 | L35: =+K35-I35 -> 15356.507
B36: SP | C36: 0 | D36: Tangible Assets | E36: =+_xlfn.NUMBERVALUE(LEFT(F36,6)) -> 100429 | F36: 100429 - F/Amm Fabbricati Ind.Li E Comm. Li | H36: 299457.1 | I36: =+G36-H36 -> -299457.1 | J36: =+_xlfn.XLOOKUP(E36,[1]BDV!$F:$F,[1]BDV!$AC:$AC) -> -294384.2 | K36: =+J36/6*8 -> -392512.27 | L36: =+K36-I36 -> -93055.167
B37: SP | C37: 0 | D37: Tangible Assets | E37: =+_xlfn.NUMBERVALUE(LEFT(F37,6)) -> 100431 | F37: 100431 - F/Amm Costruzioni Leggere | H37: 74989 | I37: =+G37-H37 -> -74989 | J37: =+_xlfn.XLOOKUP(E37,[1]BDV!$F:$F,[1]BDV!$AC:$AC) -> -74338.24 | K37: =+J37/6*8 -> -99117.653 | L37: =+K37-I37 -> -24128.653
B38: SP | C38: 0 | D38: Tangible Assets | E38: =+_xlfn.NUMBERVALUE(LEFT(F38,6)) -> 100433 | F38: 100433 - F/Amm Macchinari | H38: 36919.34 | I38: =+G38-H38 -> -36919.34 | J38: =+_xlfn.XLOOKUP(E38,[1]BDV!$F:$F,[1]BDV!$AC:$AC) -> -36919.34 | K38: =+J38/6*8 -> -49225.787 | L38: =+K38-I38 -> -12306.447
B39: SP | C39: 0 | D39: Tangible Assets | E39: =+_xlfn.NUMBERVALUE(LEFT(F39,6)) -> 100435 | F39: 100435 - F/Amm Attrezzatura Industriali E Commerciali | H39: 652334.16 | I39: =+G39-H39 -> -652334.16 | J39: =+_xlfn.XLOOKUP(E39,[1]BDV!$F:$F,[1]BDV!$AC:$AC) -> -638216.7 | K39: =+J39/6*8 -> -850955.6 | L39: =+K39-I39 -> -198621.44
B40: SP | C40: 0 | D40: Tangible Assets | E40: =+_xlfn.NUMBERVALUE(LEFT(F40,6)) -> 100437 | F40: 100437 - F/Amm Attrezzatura Varia E Minuta | H40: 74803.03 | I40: =+G40-H40 -> -74803.03 | J40: =+_xlfn.XLOOKUP(E40,[1]BDV!$F:$F,[1]BDV!$AC:$AC) -> -74166.88 | K40: =+J40/6*8 -> -98889.173 | L40: =+K40-I40 -> -24086.143
B41: SP | C41: 0 | D41: Tangible Assets | E41: =+_xlfn.NUMBERVALUE(LEFT(F41,6)) -> 100439 | F41: 100439 - F/Amm Impianti Generici | H41: 329143.84 | I41: =+G41-H41 -> -329143.84 | J41: =+_xlfn.XLOOKUP(E41,[1]BDV!$F:$F,[1]BDV!$AC:$AC) -> -326493.87 | K41: =+J41/6*8 -> -435325.16 | L41: =+K41-I41 -> -106181.32
B42: SP | C42: 0 | D42: Tangible Assets | E42: =+_xlfn.NUMBERVALUE(LEFT(F42,6)) -> 100441 | F42: 100441 - F/Amm Impianti Specifici | H42: 478748.5 | I42: =+G42-H42 -> -478748.5 | J42: =+_xlfn.XLOOKUP(E42,[1]BDV!$F:$F,[1]BDV!$AC:$AC) -> -473050.14 | K42: =+J42/6*8 -> -630733.52 | L42: =+K42-I42 -> -151985.02
B43: SP | C43: 0 | D43: Tangible Assets | E43: =+_xlfn.NUMBERVALUE(LEFT(F43,6)) -> 100443 | F43: 100443 - F/Amm Mobili E Macchine Ordinarie D'ufficio | H43: 395317.49 | I43: =+G43-H43 -> -395317.49 | J43: =+_xlfn.XLOOKUP(E43,[1]BDV!$F:$F,[1]BDV!$AC:$AC) -> -390059.69 | K43: =+J43/6*8 -> -520079.59 | L43: =+K43-I43 -> -124762.1
B44: SP | C44: 0 | D44: Tangible Assets | E44: =+_xlfn.NUMBERVALUE(LEFT(F44,6)) -> 100445 | F44: 100445 - F/Amm Macchine Elettromeccaniche D'ufficio | H44: 237452.24 | I44: =+G44-H44 -> -237452.24 | J44: =+_xlfn.XLOOKUP(E44,[1]BDV!$F:$F,[1]BDV!$AC:$AC) -> -230985.9 | K44: =+J44/6*8 -> -307981.2 | L44: =+K44-I44 -> -70528.96
...

Sheet delta only CVS
G2: Costi Diretti | H2: =+SUMIFS(L:L,D:D,G2) -> -93229.13 | I2: minori costi
G3: Overheads | H3: =+SUMIFS(L:L,D:D,G3) -> -132393.35 | I3: minori costi
G4: Canone | H4: =+SUMIFS(L:L,D:D,G4) -> -1312065.4 | I4: Ricavi Inferiori
G5: Costruzioni Interne | H5: =+SUMIFS(L:L,D:D,G5) -> -527633.79 | I5: meno CapEx
G6: Personnel Costs | H6: =+SUMIFS(L:L,D:D,G6) -> -80137.637 | I6: minori costi
G7: Taxes overheads | H7: =+SUMIFS(L:L,D:D,G7) -> 5561.6633 | I7: più costi
G9: Extraordinary Item (Attive) | H9: =+SUMIFS(L:L,D:D,G9) -> -14015.393
G10: Other Revenues | H10: =+SUMIFS(L:L,D:D,G10) -> 1906.4267
G11: Depreciation and amortization | H11: =+SUMIFS(L:L,D:D,G11) -> 362659.95
G12: Financial Income | H12: =+SUMIFS(L:L,D:D,G12) -> 244924.5
G13: Financial Expenses | H13: =+SUMIFS(L:L,D:D,G13) -> 66454.707
G14: Taxes | H14: =+SUMIFS(L:L,D:D,G14) -> -34406
B16: Quadro | C16: Altro | D16: Ricla MG esteso | E16: Conto | F16: Account | G16: Debit | H16: Credit | I16: Agosto | J16: Giugno | K16: Giu RR | L16: Delta
B17: CE | C17: C | D17: Magazzino | E17: 800405 | F17: 800405 - Materie Prime C/Rim Iniziali | G17: 2131263.2 | I17: 2131263.2 | J17: 2131263.2 | K17: =+J17/6*8 -> 2841684.3 | L17: =+K17-I17 -> 710421.07
B18: CE | C18: C | D18: Depreciation and amortization | E18: 760601 | F18: 760601 - Amm.To Lav. Straord. Beni Di Terzi | G18: 4362356 | I18: 4362356 | J18: 3547371 | K18: =+J18/6*8 -> 4729828 | L18: =+K18-I18 -> 367471.93
B19: CE | C19: C | D19: Costi Diretti | E19: 680201 | F19: 680201 - Merci C/Acquisti Nazionali | G19: 7647933.3 | I19: 7647933.3 | J19: 5934074.4 | K19: =+J19/6*8 -> 7912099.2 | L19: =+K19-I19 -> 264165.87
B20: CE | C20: C | D20: Financial Income | E20: 900201 | F20: 900201 - Differenziale Derivati Di Copertura | H20: 214475.36 | I20: -214475.36 | J20: 16821.08 | K20: =+J20/6*8 -> 22428.107 | L20: =+K20-I20 -> 236903.47
B21: CE | C21: C | D21: Costi Diretti | E21: 700203 | F21: 700203 - Lavoraz. Di Terzi P/Prod. Servizi | G21: 11105305 | I21: 11105305 | J21: 8415918.3 | K21: =+J21/6*8 -> 11221224 | L21: =+K21-I21 -> 115919.65
B22: CE | C22: C | D22: Overheads | E22: 700407 | F22: 700407 - Comp. Prof. Attinenti Attivita' C/Rit. | G22: 1078802.8 | I22: 1078802.8 | J22: 887136.03 | K22: =+J22/6*8 -> 1182848 | L22: =+K22-I22 -> 104045.28
B23: CE | C23: C | D23: Financial Expenses | E23: 920215 | F23: 920215 - Interessi Da Debiti Verso Banche_Linea Senior | G23: 487688.42 | I23: 487688.42 | J23: 418991.35 | K23: =+J23/6*8 -> 558655.13 | L23: =+K23-I23 -> 70966.713
B24: CE | C24: C | D24: Overheads | E24: 700409 | F24: 700409 - Comp. Prof. Attinenti Attivita' | G24: 403472.76 | I24: 403472.76 | J24: 351421.82 | K24: =+J24/6*8 -> 468562.43 | L24: =+K24-I24 -> 65089.667
B25: CE | C25: C | D25: Taxes overheads | E25: 880207 | F25: 880207 - Altre Imposte E Tasse Inded. | G25: 166401.98 | I25: 166401.98 | J25: 165226.79 | K25: =+J25/6*8 -> 220302.39 | L25: =+K25-I25 -> 53900.407
B26: CE | C26: C | D26: Overheads | E26: 701607 | F26: 701607 - Pubb. E Markt | G26: 161022.3 | I26: 161022.3 | J26: 155751.2 | K26: =+J26/6*8 -> 207668.27 | L26: =+K26-I26 -> 46645.967
B27: CE | C27: C | D27: Personnel Costs | E27: 740609 | F27: 740609 - Oneri Previdenziali I.N.P.S. - Dirigenti | G27: 336838.91 | I27: 336838.91 | J27: 279271.38 | K27: =+J27/6*8 -> 372361.84 | L27: =+K27-I27 -> 35522.93
B28: CE | C28: C | D28: Personnel Costs | E28: 741201 | F28: 741201 - Trattamento Di Fine Rapporto | G28: 140397.95 | I28: 140397.95 | J28: 127457.54 | K28: =+J28/6*8 -> 169943.39 | L28: =+K28-I28 -> 29545.437
B29: CE | C29: C | D29: Overheads | E29: 700213 | F29: 700213 - Manut. E Rip. Ord. Beni Di Terzi | G29: 77150.23 | I29: 77150.23 | J29: 77150.23 | K29: =+J29/6*8 -> 102866.97 | L29: =+K29-I29 -> 25716.743
B30: CE | C30: C | D30: Overheads | E30: 702411 | F30: 702411 - Altre Assicurazioni | G30: 191525.62 | I30: 191525.62 | J30: 161362.36 | K30: =+J30/6*8 -> 215149.81 | L30: =+K30-I30 -> 23624.193
B31: CE | C31: C | D31: Personnel Costs | E31: 741607 | F31: 741607 - Welfare | G31: 97340.13 | I31: 97340.13 | J31: 86889.27 | K31: =+J31/6*8 -> 115852.36 | L31: =+K31-I31 -> 18512.23
B32: CE | C32: C | D32: Overheads | E32: 700801 | F32: 700801 - Commissioni Bancarie | G32: 80784.01 | I32: 80784.01 | J32: 68487.55 | K32: =+J32/6*8 -> 91316.733 | L32: =+K32-I32 -> 10532.723
... B37: CE | C37: C | D37: Overheads | E37: 702405 | F37: 702405 - Assicurazioni R.C. | G37: 30902.54 | I37: 30902.54 | J37: 29972.01 | K37: =+J37/6*8 -> 39962.68 | L37: =+K37-I37 -> 9060.14
B38: CE | C38: R | D38: Financial Income | E38: 900209 | F38: 900209 - Interessi Attivi | H38: 19111.54 | I38: -19111.54 | J38: -8317.88 | K38: =+J38/6*8 -> -11090.507 | L38: =+K38-I38 -> 8021.0333
B39: CE | C39: C | D39: Overheads | E39: 702201 | F39: 702201 - Spese Telefoniche | G39: 70568.7 | I39: 70568.7 | J39: 58085.49 | K39: =+J39/6*8 -> 77447.32 | L39: =+K39-I39 -> 6878.62
B40: CE | C40: C | D40: Overheads | E40: 700209 | F40: 700209 - Manut. E Rip. Autocarri | G40: 58945.79 | I40: 58945.79 | J40: 48624.7 | K40: =+J40/6*8 -> 64832.933 | L40: =+K40-I40 -> 5887.1433
B41: CE | C41: C | D41: Overheads | E41: 881001 | F41: 881001 - Erog. Liberali Ded. | G41: 24265 | I41: 24265 | J41: 22265 | K41: =+J41/6*8 -> 29686.667 | L41: =+K41-I41 -> 5421.6667
B42: CE | C42: R | D42: Extraordinary Item (Attive) | E42: 660407 | F42: 660407 - Sopravvenienze Attive | H42: 23438.42 | I42: -23438.42 | J42: -13766.53 | K42: =+J42/6*8 -> -18355.373 | L42: =+K42-I42 -> 5083.0467
B43: CE | C43: C | D43: Overheads | E43: 700815 | F43: 700815 - Spese Per Trasferte | G43: 119529.99 | I43: 119529.99 | J43: 93192.04 | K43: =+J43/6*8 -> 124256.05 | L43: =+K43-I43 -> 4726.0633
B44: CE | C44: C | D44: Personnel Costs | E44: 740207 | F44: 740207 - Rimborsi Da Nota Spese | G44: 101489.14 | I44: 101489.14 | J44: 79544.46 | K44: =+J44/6*8 -> 106059.28 | L44: =+K44-I44 -> 4570.14
B45: CE | C45: C | D45: Personnel Costs | E45: 700403 | F45: 700403 - Compensi A Collaboratori Co.Co.Co. | G45: 242668.54 | I45: 242668.54 | J45: 184694.93 | K45: =+J45/6*8 -> 246259.91 | L45: =+K45-I45 -> 3591.3667
B46: CE | C46: R | D46: Other Revenues | E46: 660403 | F46: 660403 - Plusvalenze | H46: 3152.3 | I46: -3152.3 | J46: 0 | K46: =+J46/6*8 -> 0 | L46: =+K46-I46 -> 3152.3
B47: CE | C47: C | D47: Overheads | E47: 702407 | F47: 702407 - Assicurazioni R.C.A. Parz. Deduc. | G47: 15259.39 | I47: 15259.39 | J47: 13689.72 | K47: =+J47/6*8 -> 18252.96 | L47: =+K47-I47 -> 2993.57
...

Sheet Sheet2
J1: =+SUM(J3:J1032) -> 27929.458 | K1: =+SUM(K3:K1032) -> 37239.277 | L1: =+SUM(L3:L1032) -> 38954.777
B2: Chiave | C2: Entity | D2: Seller | E2: BU | F2: Business Stream | G2: Type of contract | H2: Codice Financial Commesse | I2: Comuni | J2: Giugno | K2: RR Giugno | L2: Agosto | M2: Delta
B3: =+I3&H3 -> Varazze | C3: CVS | D3: Organic | E3: North West | F3: Public Streetlighting | G3: PPP | I3: Varazze | J3: =+_xlfn.XLOOKUP(B3,Sheet3!B:B,Sheet3!J:J,0) -> 0 | K3: =+J3/6*8 -> 0 | L3: 0 | M3: =+L3-K3 -> 0
B4: =+I4&H4 -> Lerici PL | C4: CVS | D4: Organic | E4: North West | F4: Public Streetlighting | G4: PPP | I4: Lerici PL | J4: =+_xlfn.XLOOKUP(B4,Sheet3!B:B,Sheet3!J:J,0) -> 0 | K4: =+J4/6*8 -> 0 | L4: 0 | M4: =+L4-K4 -> 0
B5: =+I5&H5 -> Levanto | C5: CVS | D5: Organic | E5: North West | F5: Public Streetlighting | G5: PPP | I5: Levanto | J5: =+_xlfn.XLOOKUP(B5,Sheet3!B:B,Sheet3!J:J,0) -> 0 | K5: =+J5/6*8 -> 0 | L5: 0 | M5: =+L5-K5 -> 0
B6: =+I6&H6 -> SoriPPP-IPU-I852-01 | C6: CVS | D6: Organic | E6: North West | F6: Public Streetlighting | G6: PPP | H6: PPP-IPU-I852-01 | I6: Sori | J6: =+_xlfn.XLOOKUP(B6,Sheet3!B:B,Sheet3!J:J,0) -> 0 | K6: =+J6/6*8 -> 0 | L6: 0 | M6: =+L6-K6 -> 0
B7: =+I7&H7 -> Avezzano 3SEC-PHV-A515-01 | C7: CVS | D7: Organic | E7: Centre | F7: Photovoltaic | G7: Photovoltaic | H7: SEC-PHV-A515-01 | I7: Avezzano 3 | J7: =+_xlfn.XLOOKUP(B7,Sheet3!B:B,Sheet3!J:J,0) -> 0 | K7: =+J7/6*8 -> 0 | L7: 0 | M7: =+L7-K7 -> 0
B8: =+I8&H8 -> Avezzano 4SEC-PHV-A515-02 | C8: CVS | D8: Organic | E8: Centre | F8: Photovoltaic | G8: Photovoltaic | H8: SEC-PHV-A515-02 | I8: Avezzano 4 | J8: =+_xlfn.XLOOKUP(B8,Sheet3!B:B,Sheet3!J:J,0) -> 0 | K8: =+J8/6*8 -> 0 | L8: 0 | M8: =+L8-K8 -> 0
B9: =+I9&H9 -> GiulianovaSEC-PHV-E058-01 | C9: CVS | D9: Organic | E9: Centre | F9: Photovoltaic | G9: Photovoltaic | H9: SEC-PHV-E058-01 | I9: Giulianova | J9: =+_xlfn.XLOOKUP(B9,Sheet3!B:B,Sheet3!J:J,0) -> 0 | K9: =+J9/6*8 -> 0 | L9: 0 | M9: =+L9-K9 -> 0
B10: =+I10&H10 -> Montorio 1SEC-PHV-F690-01 | C10: CVS | D10: Organic | E10: Centre | F10: Photovoltaic | G10: Photovoltaic | H10: SEC-PHV-F690-01 | I10: Montorio 1 | J10: =+_xlfn.XLOOKUP(B10,Sheet3!B:B,Sheet3!J:J,0) -> 0 | K10: =+J10/6*8 -> 0 | L10: 0 | M10: =+L10-K10 -> 0
B11: =+I11&H11 -> Montorio 3SEC-PHV-F690-02 | C11: CVS | D11: Organic | E11: Centre | F11: Photovoltaic | G11: Photovoltaic | H11: SEC-PHV-F690-02 | I11: Montorio 3 | J11: =+_xlfn.XLOOKUP(B11,Sheet3!B:B,Sheet3!J:J,0) -> 0 | K11: =+J11/6*8 -> 0 | L11: 0 | M11: =+L11-K11 -> 0
B12: =+I12&H12 -> Montorio 4SEC-PHV-F690-03 | C12: CVS | D12: Organic | E12: Centre | F12: Photovoltaic | G12: Photovoltaic | H12: SEC-PHV-F690-03 | I12: Montorio 4 | J12: =+_xlfn.XLOOKUP(B12,Sheet3!B:B,Sheet3!J:J,0) -> 0 | K12: =+J12/6*8 -> 0 | L12: 0 | M12: =+L12-K12 -> 0
B13: =+I13&H13 -> Sant'Arpino | C13: CVS | D13: Organic | E13: South | F13: Public Streetlighting | G13: PPP | I13: Sant'Arpino | J13: =+_xlfn.XLOOKUP(B13,Sheet3!B:B,Sheet3!J:J,0) -> 0 | K13: =+J13/6*8 -> 0 | L13: 0 | M13: =+L13-K13 -> 0
B14: =+I14&H14 -> Avigliano Cemetery | C14: CVS | D14: Organic | E14: South | F14: Cemetary Services | G14: PPP | I14: Avigliano Cemetery | J14: =+_xlfn.XLOOKUP(B14,Sheet3!B:B,Sheet3!J:J,0) -> 0 | K14: =+J14/6*8 -> 0 | L14: 0 | M14: =+L14-K14 -> 0
B15: =+I15&H15 -> Filiano Cemetery | C15: CVS | D15: Organic | E15: South | F15: Cemetary Services | G15: PPP | I15: Filiano Cemetery | J15: =+_xlfn.XLOOKUP(B15,Sheet3!B:B,Sheet3!J:J,0) -> 0 | K15: =+J15/6*8 -> 0 | L15: 0 | M15: =+L15-K15 -> 0
B16: =+I16&H16 -> San Marzano di San GiuseppePPP-IPU-I018-01 | C16: CVS | D16: Organic | E16: South | F16: Public Streetlighting | G16: PPP | H16: PPP-IPU-I018-01 | I16: San Marzano di San Giuseppe | J16: =+_xlfn.XLOOKUP(B16,Sheet3!B:B,Sheet3!J:J,0) -> 0 | K16: =+J16/6*8 -> 0 | L16: 0 | M16: =+L16-K16 -> 0
B17: =+I17&H17 -> Frignano | C17: CVS | D17: Organic | E17: South | F17: Public Streetlighting | G17: PPP | I17: Frignano | J17: =+_xlfn.XLOOKUP(B17,Sheet3!B:B,Sheet3!J:J,0) -> 0 | K17: =+J17/6*8 -> 0 | L17: 0 | M17: =+L17-K17 -> 0
B18: =+I18&H18 -> Gricignano di Aversa | C18: CVS | D18: Organic | E18: South | F18: Public Streetlighting | G18: PPP | I18: Gricignano di Aversa | J18: =+_xlfn.XLOOKUP(B18,Sheet3!B:B,Sheet3!J:J,0) -> 0 | K18: =+J18/6*8 -> 0 | L18: 0 | M18: =+L18-K18 -> 0
B19: =+I19&H19 -> Torano Castello | C19: CVS | D19: Organic | E19: South | F19: Public Streetlighting | G19: PPP | I19: Torano Castello | J19: =+_xlfn.XLOOKUP(B19,Sheet3!B:B,Sheet3!J:J,0) -> 0 | K19: =+J19/6*8 -> 0 | L19: 0 | M19: =+L19-K19 -> 0
B20: =+I20&H20 -> Piano di SorrentoPPP-IPU-G568-01 | C20: CVS | D20: Organic | E20: South | F20: Public Streetlighting | G20: PPP | H20: PPP-IPU-G568-01 | I20: Piano di Sorrento | J20: =+_xlfn.XLOOKUP(B20,Sheet3!B:B,Sheet3!J:J,0) -> 0 | K20: =+J20/6*8 -> 0 | L20: 0 | M20: =+L20-K20 -> 0
B21: =+I21&H21 -> Giardini-Naxos | C21: CVS | D21: Organic | E21: South | F21: Public Streetlighting | G21: PPP | I21: Giardini-Naxos | J21: =+_xlfn.XLOOKUP(B21,Sheet3!B:B,Sheet3!J:J,0) -> 0 | K21: =+J21/6*8 -> 0 | L21: 0 | M21: =+L21-K21 -> 0
B22: =+I22&H22 -> Copertino 1SEC-PHV-C978-01 | C22: CVS | D22: Organic | E22: South | F22: Photovoltaic | G22: Photovoltaic | H22: SEC-PHV-C978-01 | I22: Copertino 1 | J22: =+_xlfn.XLOOKUP(B22,Sheet3!B:B,Sheet3!J:J,0) -> 0 | K22: =+J22/6*8 -> 0 | L22: 0 | M22: =+L22-K22 -> 0
B23: =+I23&H23 -> Copertino 2SEC-PHV-C978-02 | C23: CVS | D23: Organic | E23: South | F23: Photovoltaic | G23: Photovoltaic | H23: SEC-PHV-C978-02 | I23: Copertino 2 | J23: =+_xlfn.XLOOKUP(B23,Sheet3!B:B,Sheet3!J:J,0) -> 0 | K23: =+J23/6*8 -> 0 | L23: 0 | M23: =+L23-K23 -> 0
B24: =+I24&H24 -> Campi 1 | C24: CVS | D24: Organic | E24: South | F24: Photovoltaic | G24: Photovoltaic | I24: Campi 1 | J24: =+_xlfn.XLOOKUP(B24,Sheet3!B:B,Sheet3!J:J,0) -> 0 | K24: =+J24/6*8 -> 0 | L24: 0 | M24: =+L24-K24 -> 0
B25: =+I25&H25 -> Belvedere Marittimo | C25: CVS | D25: Jovit | E25: South | F25: Public Streetlighting | G25: PPP | I25: Belvedere Marittimo | J25: =+_xlfn.XLOOKUP(B25,Sheet3!B:B,Sheet3!J:J,0) -> 0 | K25: =+J25/6*8 -> 0 | L25: 0 | M25: =+L25-K25 -> 0
B26: =+I26&H26 -> Roccamonfina | C26: CVS | D26: Jovit | E26: South | F26: Public Streetlighting | G26: PPP | I26: Roccamonfina | J26: =+_xlfn.XLOOKUP(B26,Sheet3!B:B,Sheet3!J:J,0) -> 0 | K26: =+J26/6*8 -> 0 | L26: 0 | M26: =+L26-K26 -> 0
B27: =+I27&H27 -> Sesto Campano | C27: CVS | D27: Jovit | E27: Centre | F27: Public Streetlighting | G27: PPP | I27: Sesto Campano | J27: =+_xlfn.XLOOKUP(B27,Sheet3!B:B,Sheet3!J:J,0) -> 0 | K27: =+J27/6*8 -> 0 | L27: 0 | M27: =+L27-K27 -> 0
B28: =+I28&H28 -> RivarossaPPP-IPU-H344-01 | C28: CVS | D28: Samsic | E28: North West | F28: Public Streetlighting | G28: PPP | H28: PPP-IPU-H344-01 | I28: Rivarossa | J28: =+_xlfn.XLOOKUP(B28,Sheet3!B:B,Sheet3!J:J,0) -> 0 | K28: =+J28/6*8 -> 0 | L28: 0 | M28: =+L28-K28 -> 0
B29: =+I29&H29 -> Torre D'IsolaPPP-IPU-L269-01 | C29: CVS | D29: Samsic | E29: North West | F29: Public Streetlighting | G29: PPP | H29: PPP-IPU-L269-01 | I29: Torre D'Isola | J29: =+_xlfn.XLOOKUP(B29,Sheet3!B:B,Sheet3!J:J,0) -> 0 | K29: =+J29/6*8 -> 0 | L29: 0 | M29: =+L29-K29 -> 0
B30: =+I30&H30 -> Santo Stefano LodigianoPPP-IPU-I362-01 | C30: CVS | D30: Samsic | E30: North West | F30: Public Streetlighting | G30: PPP | H30: PPP-IPU-I362-01 | I30: Santo Stefano Lodigiano | J30: =+_xlfn.XLOOKUP(B30,Sheet3!B:B,Sheet3!J:J,0) -> 0 | K30: =+J30/6*8 -> 0 | L30: 0 | M30: =+L30-K30 -> 0
B31: =+I31&H31 -> SecugnagoPPP-IPU-I561-01 | C31: CVS | D31: Samsic | E31: North West | F31: Public Streetlighting | G31: PPP | H31: PPP-IPU-I561-01 | I31: Secugnago | J31: =+_xlfn.XLOOKUP(B31,Sheet3!B:B,Sheet3!J:J,0) -> 0 | K31: =+J31/6*8 -> 0 | L31: 0 | M31: =+L31-K31 -> 0
B32: =+I32&H32 -> Loro CiuffennaPPP-IPU-E693-01 | C32: CVS | D32: Samsic | E32: Centre | F32: Public Streetlighting | G32: PPP | H32: PPP-IPU-E693-01 | I32: Loro Ciuffenna | J32: =+_xlfn.XLOOKUP(B32,Sheet3!B:B,Sheet3!J:J,0) -> 0 | K32: =+J32/6*8 -> 0 | L32: 0 | M32: =+L32-K32 -> 0
B33: =+I33&H33 -> Ricigliano | C33: CVS | D33: Alfano Luce | E33: South | F33: Public Streetlighting | G33: PPP | I33: Ricigliano | J33: =+_xlfn.XLOOKUP(B33,Sheet3!B:B,Sheet3!J:J,0) -> 0 | K33: =+J33/6*8 -> 0 | L33: 0 | M33: =+L33-K33 -> 0
B34: =+I34&H34 -> Serino | C34: CVS | D34: Alfano Luce | E34: South | F34: Public Streetlighting | G34: PPP | I34: Serino | J34: =+_xlfn.XLOOKUP(B34,Sheet3!B:B,Sheet3!J:J,0) -> 0 | K34: =+J34/6*8 -> 0 | L34: 0 | M34: =+L34-K34 -> 0
B35: =+I35&H35 -> San Cipriano PicentinoPPP-IPU-H800-01 | C35: CVS | D35: Alfano Luce | E35: South | F35: Public Streetlighting | G35: PPP | H35: PPP-IPU-H800-01 | I35: San Cipriano Picentino | J35: =+_xlfn.XLOOKUP(B35,Sheet3!B:B,Sheet3!J:J,0) -> 0 | K35: =+J35/6*8 -> 0 | L35: 0 | M35: =+L35-K35 -> 0
B36: =+I36&H36 -> Vietri sul Mare | C36: CVS | D36: Alfano Luce | E36: South | F36: Public Streetlighting | G36: PPP | I36: Vietri sul Mare | J36: =+_xlfn.XLOOKUP(B36,Sheet3!B:B,Sheet3!J:J,0) -> 0 | K36: =+J36/6*8 -> 0 | L36: 0 | M36: =+L36-K36 -> 0
B37: =+I37&H37 -> Umbertide | C37: CVS | D37: Tetra Engineering | E37: Centre | F37: Public Streetlighting | G37: PPP | I37: Umbertide | J37: =+_xlfn.XLOOKUP(B37,Sheet3!B:B,Sheet3!J:J,0) -> 0 | K37: =+J37/6*8 -> 0 | L37: 0 | M37: =+L37-K37 -> 0
B38: =+I38&H38 -> Lizzanello | C38: CVS | D38: Ege Global Service | E38: South | F38: Public Streetlighting | G38: PPP | I38: Lizzanello | J38: =+_xlfn.XLOOKUP(B38,Sheet3!B:B,Sheet3!J:J,0) -> 0 | K38: =+J38/6*8 -> 0 | L38: 0 | M38: =+L38-K38 -> 0
B39: =+I39&H39 -> San Donato Milanese | C39: CVS | D39: Ege Global Service | E39: South | F39: Public Streetlighting | G39: PPP | I39: San Donato Milanese | J39: =+_xlfn.XLOOKUP(B39,Sheet3!B:B,Sheet3!J:J,0) -> 0 | K39: =+J39/6*8 -> 0 | L39: 0 | M39: =+L39-K39 -> 0
B40: =+I40&H40 -> Altro Not identified (Sud) 1 | C40: CVS | D40: Pipeline | E40: South | F40: Public Streetlighting | G40: PPP | I40: Altro Not identified (Sud) 1 | J40: =+_xlfn.XLOOKUP(B40,Sheet3!B:B,Sheet3!J:J,0) -> 0 | K40: =+J40/6*8 -> 0 | L40: 0 | M40: =+L40-K40 -> 0
...

Sheet Sheet3
C2: Entity | D2: Org./Inorg. | E2: BU | F2: Business Stream | G2: Type of contract | H2: Codice Financial Commesse | I2: Comuni | J2: Giugno
B3: =+I3&H3 -> Varazze | C3: CVS | D3: Organic | E3: North West | F3: Public Streetlighting | G3: PPP | I3: Varazze | J3: 0
B4: =+I4&H4 -> Lerici PL | C4: CVS | D4: Organic | E4: North West | F4: Public Streetlighting | G4: PPP | I4: Lerici PL | J4: 0
B5: =+I5&H5 -> Levanto | C5: CVS | D5: Organic | E5: North West | F5: Public Streetlighting | G5: PPP | I5: Levanto | J5: 0
B6: =+I6&H6 -> SoriPPP-IPU-I852-01 | C6: CVS | D6: Organic | E6: North West | F6: Public Streetlighting | G6: PPP | H6: PPP-IPU-I852-01 | I6: Sori | J6: 0
B7: =+I7&H7 -> Avezzano 3SEC-PHV-A515-01 | C7: CVS | D7: Organic | E7: Centre | F7: Photovoltaic | G7: Photovoltaic | H7: SEC-PHV-A515-01 | I7: Avezzano 3 | J7: 0
B8: =+I8&H8 -> Avezzano 4SEC-PHV-A515-02 | C8: CVS | D8: Organic | E8: Centre | F8: Photovoltaic | G8: Photovoltaic | H8: SEC-PHV-A515-02 | I8: Avezzano 4 | J8: 0
B9: =+I9&H9 -> GiulianovaSEC-PHV-E058-01 | C9: CVS | D9: Organic | E9: Centre | F9: Photovoltaic | G9: Photovoltaic | H9: SEC-PHV-E058-01 | I9: Giulianova | J9: 0
B10: =+I10&H10 -> Montorio 1SEC-PHV-F690-01 | C10: CVS | D10: Organic | E10: Centre | F10: Photovoltaic | G10: Photovoltaic | H10: SEC-PHV-F690-01 | I10: Montorio 1 | J10: 0
B11: =+I11&H11 -> Montorio 3SEC-PHV-F690-02 | C11: CVS | D11: Organic | E11: Centre | F11: Photovoltaic | G11: Photovoltaic | H11: SEC-PHV-F690-02 | I11: Montorio 3 | J11: 0
B12: =+I12&H12 -> Montorio 4SEC-PHV-F690-03 | C12: CVS | D12: Organic | E12: Centre | F12: Photovoltaic | G12: Photovoltaic | H12: SEC-PHV-F690-03 | I12: Montorio 4 | J12: 0
B13: =+I13&H13 -> Sant'Arpino | C13: CVS | D13: Organic | E13: South | F13: Public Streetlighting | G13: PPP | I13: Sant'Arpino | J13: 0
B14: =+I14&H14 -> Avigliano Cemetery | C14: CVS | D14: Organic | E14: South | F14: Cemetary Services | G14: PPP | I14: Avigliano Cemetery | J14: 0
B15: =+I15&H15 -> Filiano Cemetery | C15: CVS | D15: Organic | E15: South | F15: Cemetary Services | G15: PPP | I15: Filiano Cemetery | J15: 0
B16: =+I16&H16 -> San Marzano di San GiuseppePPP-IPU-I018-01 | C16: CVS | D16: Organic | E16: South | F16: Public Streetlighting | G16: PPP | H16: PPP-IPU-I018-01 | I16: San Marzano di San Giuseppe | J16: 0
B17: =+I17&H17 -> Frignano | C17: CVS | D17: Organic | E17: South | F17: Public Streetlighting | G17: PPP | I17: Frignano | J17: 0
B18: =+I18&H18 -> Gricignano di Aversa | C18: CVS | D18: Organic | E18: South | F18: Public Streetlighting | G18: PPP | I18: Gricignano di Aversa | J18: 0
B19: =+I19&H19 -> Torano Castello | C19: CVS | D19: Organic | E19: South | F19: Public Streetlighting | G19: PPP | I19: Torano Castello | J19: 0
B20: =+I20&H20 -> Piano di SorrentoPPP-IPU-G568-01 | C20: CVS | D20: Organic | E20: South | F20: Public Streetlighting | G20: PPP | H20: PPP-IPU-G568-01 | I20: Piano di Sorrento | J20: 0
B21: =+I21&H21 -> Giardini-Naxos | C21: CVS | D21: Organic | E21: South | F21: Public Streetlighting | G21: PPP | I21: Giardini-Naxos | J21: 0
B22: =+I22&H22 -> Copertino 1SEC-PHV-C978-01 | C22: CVS | D22: Organic | E22: South | F22: Photovoltaic | G22: Photovoltaic | H22: SEC-PHV-C978-01 | I22: Copertino 1 | J22: 0
B23: =+I23&H23 -> Copertino 2SEC-PHV-C978-02 | C23: CVS | D23: Organic | E23: South | F23: Photovoltaic | G23: Photovoltaic | H23: SEC-PHV-C978-02 | I23: Copertino 2 | J23: 0
B24: =+I24&H24 -> Campi 1 | C24: CVS | D24: Organic | E24: South | F24: Photovoltaic | G24: Photovoltaic | I24: Campi 1 | J24: 0
B25: =+I25&H25 -> Belvedere Marittimo | C25: CVS | D25: Jovit | E25: South | F25: Public Streetlighting | G25: PPP | I25: Belvedere Marittimo | J25: 0
B26: =+I26&H26 -> Roccamonfina | C26: CVS | D26: Jovit | E26: South | F26: Public Streetlighting | G26: PPP | I26: Roccamonfina | J26: 0
B27: =+I27&H27 -> Sesto Campano | C27: CVS | D27: Jovit | E27: Centre | F27: Public Streetlighting | G27: PPP | I27: Sesto Campano | J27: 0
B28: =+I28&H28 -> RivarossaPPP-IPU-H344-01 | C28: CVS | D28: Samsic | E28: North West | F28: Public Streetlighting | G28: PPP | H28: PPP-IPU-H344-01 | I28: Rivarossa | J28: 0
B29: =+I29&H29 -> Torre D'IsolaPPP-IPU-L269-01 | C29: CVS | D29: Samsic | E29: North West | F29: Public Streetlighting | G29: PPP | H29: PPP-IPU-L269-01 | I29: Torre D'Isola | J29: 0
B30: =+I30&H30 -> Santo Stefano LodigianoPPP-IPU-I362-01 | C30: CVS | D30: Samsic | E30: North West | F30: Public Streetlighting | G30: PPP | H30: PPP-IPU-I362-01 | I30: Santo Stefano Lodigiano | J30: 0
B31: =+I31&H31 -> SecugnagoPPP-IPU-I561-01 | C31: CVS | D31: Samsic | E31: North West | F31: Public Streetlighting | G31: PPP | H31: PPP-IPU-I561-01 | I31: Secugnago | J31: 0
B32: =+I32&H32 -> Loro CiuffennaPPP-IPU-E693-01 | C32: CVS | D32: Samsic | E32: Centre | F32: Public Streetlighting | G32: PPP | H32: PPP-IPU-E693-01 | I32: Loro Ciuffenna | J32: 0
B33: =+I33&H33 -> Ricigliano | C33: CVS | D33: Alfano Luce | E33: South | F33: Public Streetlighting | G33: PPP | I33: Ricigliano | J33: 0
B34: =+I34&H34 -> Serino | C34: CVS | D34: Alfano Luce | E34: South | F34: Public Streetlighting | G34: PPP | I34: Serino | J34: 0
B35: =+I35&H35 -> San Cipriano PicentinoPPP-IPU-H800-01 | C35: CVS | D35: Alfano Luce | E35: South | F35: Public Streetlighting | G35: PPP | H35: PPP-IPU-H800-01 | I35: San Cipriano Picentino | J35: 0
B36: =+I36&H36 -> Vietri sul Mare | C36: CVS | D36: Alfano Luce | E36: South | F36: Public Streetlighting | G36: PPP | I36: Vietri sul Mare | J36: 0
B37: =+I37&H37 -> Umbertide | C37: CVS | D37: Tetra Engineering | E37: Centre | F37: Public Streetlighting | G37: PPP | I37: Umbertide | J37: 0
B38: =+I38&H38 -> Lizzanello | C38: CVS | D38: Ege Global Service | E38: South | F38: Public Streetlighting | G38: PPP | I38: Lizzanello | J38: 0
B39: =+I39&H39 -> San Donato Milanese | C39: CVS | D39: Ege Global Service | E39: South | F39: Public Streetlighting | G39: PPP | I39: San Donato Milanese | J39: 0
B40: =+I40&H40 -> Altro Not identified (Sud) 1 | C40: CVS | D40: Pipeline | E40: South | F40: Public Streetlighting | G40: PPP | I40: Altro Not identified (Sud) 1 | J40: 0
B41: =+I41&H41 -> Altro Not identified (Centre) | C41: CVS | D41: Pipeline | E41: Centre | F41: Public Streetlighting | G41: PPP | I41: Altro Not identified (Centre) | J41: 0
...
