Workbook

Sheet Riepilogo Non Recurring
B1: 46023 | C1: 46054 | D1: 46082 | E1: 46113 | F1: 46143 | G1: 46174 | H1: 46204 | I1: 46235 | J1: 46266 | K1: 46296 | L1: 46327 | M1: 46357
A2: Non recurring | B2: =SUM(B3:B7) -> 162230.02 | C2: =SUM(C3:C7) -> 41762.22 | D2: =SUM(D3:D7) -> 171506.47 | E2: =SUM(E3:E7) -> 850823.35 | F2: =SUM(F3:F7) -> 226333.65 | G2: =SUM(G3:G7) -> 254433.28 | H2: =SUM(H3:H7) -> 119088.85 | I2: =SUM(I3:I7) -> 225190.18 | ... M2: =SUM(M3:M7) -> 0 | N2: =SUM(B2:M2) -> 2051368
A3: 700405 - Comp. Prof. Attinenti Attivita' Senza Rit. | B3: 0 | C3: 0 | D3: =+'700405'!I29+'700405'!I32 -> 3328 | E3: 0 | F3: 0 | G3: 0 | H3: =+'700405'!I85 -> 7589.77 | I3: 0
A4: 700407 - Comp. Prof. Attinenti Attivita' C/Rit. | B4: =+'700407'!I11+'700407'!I13 -> 5760.32 | C4: =+'700407'!I16 -> 979.17 | D4: 0 | E4: =+'700407'!I28+'700407'!I29+'700407'!I30+'700407'!I31+'700407'!I32+'700407'!I33+'700407'!I34 -> 579950.15 | F4: =+'700407'!I40+'700407'!I43 -> 31200 | G4: =+'700407'!I47+'700407'!I48+'700407'!I50+'700407'!I57+'700407'!I58+'700407'!I59 -> 35323.24 | H4: =+'700407'!I65+'700407'!I66+'700407'!I67 -> 26988 | I4: =+'700407'!I72+'700407'!I73+'700407'!I74+'700407'!I76+'700407'!I79 -> 43680
A5: 700409 - Comp. Prof. Attinenti Attivita' | B5: =+'700409'!I16 -> 112500 | C5: 0 | D5: =+'700409'!I22 -> 9920 | E5: =+'700409'!I35 -> 31250 | F5: 0 | G5: =+'700409'!I49+'700409'!I57 -> 31250 | H5: 0 | I5: =+'700409'!I73 -> 9280
A6: 702001 - Spese Di Consulenza | B6: =+'702001'!I13+'702001'!I16 -> 42012 | C6: =+'702001'!I19+'702001'!I20+'702001'!I22 -> 38760 | D6: =+'702001'!I29+'702001'!I30+'702001'!I31+'702001'!I32+'702001'!I33+'702001'!I37+'702001'!I38+'702001'!I39+'702001'!I40+'702001'!I41+'702001'!I43+'702001'!I44 -> 156644.11 | E6: =+'702001'!I49+'702001'!I50+'702001'!I52+'702001'!I56 -> 238032 | F6: =+'702001'!I57+'702001'!I60+'702001'!I61+'702001'!I63+'702001'!I64+'702001'!I67 -> 195133.65 | G6: =+'702001'!I70+'702001'!I71+'702001'!I74+'702001'!I75+'702001'!I76+'702001'!I78+'702001'!I81+'702001'!I82+'702001'!I83+'702001'!I85 -> 186622.54 | H6: =+'702001'!I90+'702001'!I92+'702001'!I93+'702001'!I94+'702001'!I95+'702001'!I96+'702001'!I101+'702001'!I105+'702001'!I107 -> 81173.09 | I6: =+'702001'!I112+'702001'!I113+'702001'!I114+'702001'!I120+'702001'!I121 -> 171372
A7: 700815 - Spese Per Trasferte | B7: =+'700815'!I50+'700815'!I101+'700815'!I107+'700815'!I125 -> 1957.7 | C7: =+'700815'!I200+'700815'!I211+'700815'!I238+'700815'!I267 -> 2023.05 | D7: =+'700815'!I319+'700815'!I381+'700815'!I398+'700815'!I399 -> 1614.36 | E7: =+'700815'!I577+'700815'!I684+'700815'!I694+'700815'!I703+'700815'!I708+'700815'!I717 -> 1591.2 | F7: 0 | G7: =+'700815'!I1155 -> 1237.5 | H7: =+'700815'!I1211+'700815'!I1223+'700815'!I1244+'700815'!I1271+'700815'!I1351+'700815'!I1354+'700815'!I1395 -> 3337.99 | I7: =+'700815'!I1403 -> 858.18

Sheet Costi di Prog.one
A1: COSTI DI PROGETTAZIONE | B1: DATA | C1: FORNITORE | D1: TOTALE
A2: 700405 - Comp. Prof. Attinenti Attivita' Senza Rit. | B2: 46053 | C2: MI10STUDIO SRL | D2: =+'700405'!I13 -> 16153.85
A3: 700405 - Comp. Prof. Attinenti Attivita' Senza Rit. | B3: 46053 | C3: RESTART GREEN SOLUTIONS SRL | D3: =+'700405'!I15 -> 8943.2
A4: 700405 - Comp. Prof. Attinenti Attivita' Senza Rit. | B4: 46053 | C4: RESTART ENGINEERING SRL | D4: =+'700405'!I17 -> 4230.24
A5: 700405 - Comp. Prof. Attinenti Attivita' Senza Rit. | B5: 46064 | C5: F-04337 MI10STUDIO SRL | D5: =+'700405'!I18 -> 646.15
A6: 700405 - Comp. Prof. Attinenti Attivita' Senza Rit. | B6: 46092 | C6: F-01930 RESTART GREEN SOLUTIONS SRL | D6: =+'700405'!I27 -> 26000
A7: 700405 - Comp. Prof. Attinenti Attivita' Senza Rit. | B7: 46132 | C7: F-01930 RESTART GREEN SOLUTIONS SRL | D7: =+'700405'!I40 -> 4095
A8: 700405 - Comp. Prof. Attinenti Attivita' Senza Rit. | B8: 46142 | C8: F-01930 RESTART GREEN SOLUTIONS SRL | D8: =+'700405'!I43 -> 9464
A9: 700407 - Comp. Prof. Attinenti Attivita' C/Rit. | B9: 46119 | C9: F-03690 STEFANO CALIGARA | D9: =+'700407'!I28 -> 17640
A10: Total - 700405 - Comp. Prof. Attinenti Attivita' Senza Rit. | B10: 46148 | C10: F-03613 BCM ENGINEERING S.R.L. | D10: =+'700405'!I45 -> 2652
A11: 700407 - Comp. Prof. Attinenti Attivita' C/Rit. | B11: 46168 | C11: F-04443 GMS ST.ASSOCIATO GUANELLA MONTANI SUSS | D11: =+'700407'!I43 -> 18720
A12: 700405 - Comp. Prof. Attinenti Attivita' Senza Rit. | B12: 46173 | C12: F-01911 RESTART ENERGY LAB S.R.L. | D12: =+'700405'!I50 -> 14050.85
A13: 700405 - Comp. Prof. Attinenti Attivita' Senza Rit. | B13: 46173 | C13: F-01930 RESTART GREEN SOLUTIONS SRL | D13: =+'700405'!I51 -> 13650.61
A14: 700405 - Comp. Prof. Attinenti Attivita' Senza Rit. | B14: 46173 | C14: F-01911 RESTART ENERGY LAB S.R.L. e F-01930 RESTART GREEN SOLUTIONS SRL | D14: =+'700405'!I55 -> 18281.6
A15: 700405 - Comp. Prof. Attinenti Attivita' Senza Rit. | B15: 46182 | C15: F-01911 RESTART ENERGY LAB S.R.L. | D15: 26000
A16: 700405 - Comp. Prof. Attinenti Attivita' Senza Rit. | B16: 46182 | C16: F-01911 RESTART ENERGY LAB S.R.L. | D16: 5265
A17: 700405 - Comp. Prof. Attinenti Attivita' Senza Rit. | B17: 46182 | C17: F-01911 RESTART ENERGY LAB S.R.L. | D17: 2600
A18: 700405 - Comp. Prof. Attinenti Attivita' Senza Rit. | B18: 46182 | C18: F-01911 RESTART ENERGY LAB S.R.L. | D18: 16640
A19: 700405 - Comp. Prof. Attinenti Attivita' Senza Rit. | B19: 46184 | C19: F-01930 RESTART GREEN SOLUTIONS SRL | D19: =+'700405'!I66 -> 10337.6
A20: 700405 - Comp. Prof. Attinenti Attivita' Senza Rit. | B20: 46196 | C20: F-01930 RESTART GREEN SOLUTIONS SRL | D20: =+'700405'!I68 -> 4303.94
A21: 700405 - Comp. Prof. Attinenti Attivita' Senza Rit. | B21: 46202 | C21: F-01930 RESTART GREEN SOLUTIONS SRL | D21: =+'700405'!I70 -> 3706.56
A22: 700409 - Comp. Prof. Attinenti Attivita' | B22: 46203 | C22: F-02941 MY_E_SERVICES SRLS | D22: =+'700409'!I56 -> 9828
A23: Total - 700407 - Comp. Prof. Attinenti Attivita' C/Rit. | B23: 46211 | C23: F-04443 GMS ST.ASSOCIATO GUANELLA MONTANI SUSS | D23: =+'700407'!I62 -> 30680
A24: Total - 700405 - Comp. Prof. Attinenti Attivita' Senza Rit. | B24: 46213 | C24: F-01911 RESTART ENERGY LAB S.R.L. | D24: =+'700405'!I80 -> 6179.26
A25: Total - 700405 - Comp. Prof. Attinenti Attivita' Senza Rit. | B25: 46213 | C25: F-01911 RESTART ENERGY LAB S.R.L. | D25: =+'700405'!I81 -> 19650.18
A26: Total - 700405 - Comp. Prof. Attinenti Attivita' Senza Rit. | B26: 46213 | C26: F-01911 RESTART ENERGY LAB S.R.L. | D26: =+'700405'!I82 -> 20273.34
A27: Total - 700407 - Comp. Prof. Attinenti Attivita' C/Rit. | B27: 46240 | C27: F-03690 STEFANO CALIGARA | D27: =+'700407'!I77 -> 6300
A28: Total - 700405 - Comp. Prof. Attinenti Attivita' Senza Rit. | B28: 46254 | C28: F-01911 RESTART ENERGY LAB S.R.L. | D28: =+'700405'!I90 -> 5200
A29: Total - 700405 - Comp. Prof. Attinenti Attivita' Senza Rit. | B29: 46254 | C29: F-01911 RESTART ENERGY LAB S.R.L. | D29: =+'700405'!I91 -> 14734.72
A30: Total - 700405 - Comp. Prof. Attinenti Attivita' Senza Rit. | B30: 46254 | C30: F-01911 RESTART ENERGY LAB S.R.L. | D30: =+'700405'!I92 -> 7280
A31: Total - 700405 - Comp. Prof. Attinenti Attivita' Senza Rit. | B31: 46254 | C31: F-01911 RESTART ENERGY LAB S.R.L. | D31: =+'700405'!I93 -> 16640
A32: Total - 700405 - Comp. Prof. Attinenti Attivita' Senza Rit. | B32: 46254 | C32: F-01911 RESTART ENERGY LAB S.R.L. | D32: =+'700405'!I94 -> 3120
A54: TOTALE | D54: =SUM(D2:D53) -> 363266.1

Sheet 700405
A1: CiviSmart
A2: Parent Company : CiviSmart S.p.A.
A3: CIV| Schede Contabili
A4: 1 January 2026 - 31 August 2026
A7: Account | B7: Type | C7: Date | D7: Document Number | E7: Name | F7: Memo | G7: [IL] Reference Date | H7: [IL] Reference # | I7: Debit | J7: NATURA DEL COSTO | K7: Credit | L7: Balance
A8: 70 - COSTI PER SERVIZI | L8: 0
A9: 7004 - Servizi Di Lavoro Parasub | L9: 0
A10: 700405 - Comp. Prof. Attinenti Attivita' Senza Rit. | L10: 1060008.2
B11: Journal | C11: 46053 | D11: JE-CIV-19439 | E11: Delfino Roberto Nicola e Stefano Romano | I11: 4320 | L11: 1064238.5
B12: Journal | C12: 46053 | D12: JE-CIV-19442 | I12: 72 | L12: 1064310.5
B13: Journal | C13: 46053 | D13: JE-CIV-19446 | E13: MI10STUDIO SRL | F13: Predisposizione studio di fattibilita tecnico-economica per il Comune di Canegrate (MI) nell ambito della riqualifica illuminotecnica e normativa degli impianti di pubblica illuminazione | I13: 16153.85 | J13: Costi di progettazione | L13: 1080464.3
B14: Journal | C14: 46053 | D14: JE-CIV-19987 | I14: 211.51 | L14: 1080675.8
B15: Journal | C15: 46053 | D15: JE-CIV-19087 | E15: RESTART GREEN SOLUTIONS SRL | F15: Progetto di Fattibilità Comune di Borgetto (PA) | I15: 8943.2 | J15: Costi di progettazione | L15: 1089619
B16: Journal | C16: 46053 | D16: JE-CIV-19438 | I16: 2168.98 | L16: 1091788
B17: Journal | C17: 46053 | D17: JE-CIV-19149 | E17: RESTART ENGINEERING SRL | F17: Progetto di Fattibilità Comune di San Teodoro | I17: 4230.24 | J17: Costi di progettazione | L17: 1096108
B18: Bill | C18: 46064 | D18: S/2026/0913/A | E18: F-04337 MI10STUDIO SRL | F18: Predisposizione studio di fattibilita tecnico-economica per il Comune di Canegrate (MI) nell ambito della riqualifica illuminotecnica e normativa degli impianti di pubblica illuminazione. | G18: 46049 | H18: 00013/26 | I18: 646.15 | J18: Costi di progettazione | L18: 1096754.2
B19: Bill | C19: 46064 | D19: S/2026/0910/A | E19: F-01125 Miguel Alberto Montesano | F19: Acconto Onorario D.L. e Coord. Sic. in fase di Esec., opere rifunzionalizzazione, efficientamento, manut. e gestione dell Imp.di Pubb. illuminazione (ampliamenti), del Comune di Maratea (PZ). | G19: 46058 | H19: FPR 1/26 | I19: 264 | L19: 1097018.2
B20: Bill | C20: 46073 | D20: S/2026/1361/A | E20: F-01803 NOE' COMI | G20: 46072 | H20: 6 | I20: 8112 | L20: 1105130.2
B21: Bill | C21: 46076 | D21: S/2026/1408/A | E21: F-01789 Daniele Monteduro | G21: 46073 | H21: FPR-I17/26 | I21: 4512.99 | L21: 1109643.1
B22: Journal | C22: 46081 | D22: JE-CIV-19152 | E22: Delfino Roberto Nicola | I22: 10169 | L22: 1119812.1
B23: Journal | C23: 46081 | D23: JE-CIV-19142 | E23: Delfino Roberto Nicola | I23: 20225 | L23: 1126827.1
B24: Journal | C24: 46081 | D24: JE-CIV-19160 | E24: archimede s.r.l | F24: Collaudo tecnico amministrativo Vicopisano | I24: 7015 | L24: 1128699.1
B25: Journal | C25: 46081 | D25: JE-CIV-19449 | I25: 1872 | L25: 1148924.1
B26: Journal | C26: 46081 | D26: JE-CIV-19506 | I26: 2900.35 | L26: 1151824.5
B27: Bill | C27: 46092 | D27: S/2026/1815/A | E27: F-01930 RESTART GREEN SOLUTIONS SRL | F27: Progetti di fattibilità - Comune di Milazzo, Marsala, San Marco D'Alunzio, Riesi, Caltanisetta | G27: 46081 | H27: 6 /I | I27: 26000 | J27: Costi di progettazione | L27: 1177824.5
B28: Bill | C28: 46093 | D28: S/2026/1897/A | E28: F-03613 BCM ENGINEERING S.R.L. | F28: Piano Economico e Finanziario per Promotore e/o partecipazione a Gara in Project Financing per Pubblica Illuminazione // N. 15 PEF: San Felice a Cancello, Messina, Trecchina, Cagnano Varano, Campobello di Mazzara, Borghetto, Recalbuto, Piana degli Albanesi, Sant Angelo Le Fratte, Sab Nicola Arcella, Calvanico, Roggiano Gravina, Faggiano, Pignola, Sommatino | G28: 46093 | H28: 1 | I28: 3900 | L28: 1181724.5
B29: Bill | C29: 46097 | D29: S/2026/2054/A | E29: F-03954 STELLA NAPOLEONE | F29: calcoli illuminotecnici del bando AREST per il comune di Saronno | G29: 46090 | H29: 04/2026 | I29: 2340 | J29: Consulenza tecnica | L29: 1184064.5
B30: Bill | C30: 46098 | D30: S/2026/2113/A | E30: F-01928 STEFANO ROMANO | F30: Attività di consulenza tecnica per le attività di informatizzazione degli impianti di illuminazione pubblica Cellino San Marco BR | G30: 46090 | H30: 2/2026 | I30: 2100 | L30: 1186164.5
B31: Bill | C31: 46105 | D31: S/2026/2396/A | E31: F-04414 GREENWICH S.R.L. | F31: fattura per direzione lavori Ing. Ivan De Bonis - LAVORI MONGRASSANO EFFICIENTAMENTO PUBBLICA ILLUMINAZIONE | G31: 46101 | H31: 1 | I31: 15062 | L31: 1201226.5
B32: Bill | C32: 46108 | D32: S/2026/2472/A | E32: F-04412 DAMATO GIANLUCA | F32: Consulenza strutturale // Consulenza per progettazione di plinto di fondazione per torre faro in Via Buozzi Savona Codice commessa PPP-IPU-I480-02 | G32: 46100 | H32: 12 | I32: 988 | J32: Consulenza tecnica | L32: 1202214.5
B33: Bill | C33: 46108 | D33: S/2026/2469/A | E33: F-02360 DELFINO ROBERTO NICOLA | G33: 46108 | H33: 4/FE | I33: 1872 | L33: 1204086.5
B34: Journal | C34: 46112 | D34: JE-CIV-21053 | I34: 36 | L34: 1204122.5
B35: Journal | C35: 46112 | D35: JE-CIV-21052 | I35: 900 | L35: 1205022.5
B36: Bill | C36: 46120 | D36: S/2026/2743/A | E36: F-01928 STEFANO ROMANO | F36: Attività di consulenza tecnica-comune di Manduria TA | G36: 46120 | H36: 3/2026 | I36: 2100 | L36: 1207122.5
B37: Bill | C37: 46127 | D37: S/2026/3089/A | E37: F-04308 FRANCESCO MEZZOPRETE | G37: 46126 | H37: 20 | I37: 9450 | L37: 1216572.5
B38: Bill Credit | C38: 46128 | D38: S/2026/3117/A | E38: F-04308 FRANCESCO MEZZOPRETE | G38: 46127 | H38: 2 | L38: 1217519.5
B39: Bill | C39: 46128 | D39: S/2026/3151/A | E39: F-04308 FRANCESCO MEZZOPRETE | F39: Prestazione tecnica per riconfinazione area impianto di pubblica illuminazione del Comune di Scurcola Marsicana (AQ) / | G39: 46127 | H39: 29 | I39: 947 | K39: 9450 | L39: 1208069.5
B40: Bill | C40: 46132 | D40: S/2026/3215/A | E40: F-01930 RESTART GREEN SOLUTIONS SRL | F40: PREPARAZIONE DOCUMENTAZIONE GARA AFFIDAMENTO-COMUNE DI MILAZZO (ME) | G40: 46132 | H40: 10 /I | I40: 4095 | J40: Costi di progettazione | L40: 1212164.5
B41: Journal | C41: 46142 | D41: JE-CIV-22352 | I41: 100 | L41: 1212264.5
B42: Journal | C42: 46142 | D42: JE-CIV-22353 | I42: 2502 | L42: 1221728.5
...

Sheet 700407
A1: CiviSmart
A2: Parent Company : CiviSmart S.p.A.
A3: CIV| Schede Contabili
A4: 1 January 2026 - 31 August 2026
A7: Account | B7: Type | C7: Date | D7: Document Number | E7: Name | F7: Memo | G7: [IL] Reference Date | H7: [IL] Reference # | I7: Debit | J7: NATURA DEL COSTO | K7: Credit | L7: Balance
A8: 70 - COSTI PER SERVIZI | L8: 0
A9: 7004 - Servizi Di Lavoro Parasub | L9: 0
A10: 700407 - Comp. Prof. Attinenti Attivita' C/Rit. | L10: 1443204.9
B11: Bill | C11: 46044 | D11: S/2026/0498/A | E11: F-01411 ATLANTE - CERASI Studio Notarile Associato | F11: Attività svolta dal Notaio Nicola Atlante di Roma: (*) visura camerale pre stipula; (*) verifica poteri; (*) revisione minuta; (*) stipula atto; (*) autentiche di firma; PROCURA SPECIALE (a Pietro SA NFILIPPO per conferimento poteri) rep. 73.161 racc. 37.910 in data 9 gennaio 2026; successivi adempimenti: (*) registrazione c/o l Agenzia delle Entrate di Roma 5; (*) rilascio di una copia autentica digitale per il Notaio Schiavone. | G11: 46041 | H11: 75 | I11: 560.32 | J11: 1.Spese di consulenza | L11: =L10+I11-K11 -> 1443765.2
B12: Bill | C12: 46052 | D12: S/2026/0682/A | E12: F-00348 TELESCA ROCCO DONATO | G12: 46050 | H12: FPR 1/26 | I12: 2080 | L12: =L11+I12-K12 -> 1445845.2
B13: Journal | C13: 46053 | D13: JE-CIV-19118 | F13: CONCESSIONE DEL SERVIZIO DI GESTIONE, MANUTENZIONE, EFFICIENTAMENTO ENEREGETICO E RIQUALIFICAZIONE DEGLI IMPIANTI DI PUBBLICA ILLUMINAZIONE- Vibonati | I13: 5200 | J13: 1.Spese di consulenza | L13: =L12+I13-K13 -> 1451045.2
B14: Journal | C14: 46053 | D14: JE-CIV-18132 | I14: 10550 | L14: =L13+I14-K14 -> 1461595.2
B15: Journal | C15: 46053 | D15: JE-CIV-19438 | I15: 8000 | L15: =L14+I15-K15 -> 1469595.2
B16: Bill | C16: 46058 | D16: S/2026/0800/A | E16: F-01411 ATLANTE - CERASI Studio Notarile Associato | F16: ATTIVITA SVOLTA DAL NOTAIO NICOLA ATLANTE DI ROMA: (*) visura camerale pre stipula; (*) verifica poteri; (*) predisposizione, redazione, revisione e correzione minute; (*) stipula atti; (*) autentich e di firma; 1) PROCURA (a Vito Telesca per conferimento poteri) rep. 73.259 racc. 37.946 in data 29 gennaio 2026; successivi adempimenti: (*) registrazione c/o l Agenzia delle Entrate di Roma 5; (* ) rilascio di una copia autentica cartacea per la società: 2) PROCURA SPECIALE in bollo (a Vito Telesca per acquistare area urbana in Comune di Campi Salentina) rep. 72.069 in data 29 gennaio 2026; ( *) rilascio originale alla società. | G16: 46057 | H16: 195 | I16: 979.17 | J16: 1.Spese di consulenza | L16: =L15+I16-K16 -> 1470574.4
B17: Bill | C17: 46070 | D17: S/2026/1235/A | E17: F-03093 QUI ASSICURAZIONI S.R.L. | G17: 46062 | H17: AF01 159/26 | I17: 419.29 | L17: =L16+I17-K17 -> 1470993.7
B18: Bill | C18: 46071 | D18: S/2026/1285/A | E18: F-04366 ING.RUSSO DOMENICO | G18: 46063 | H18: 01 | I18: 832 | L18: =L17+I18-K18 -> 1471825.7
B19: Bill | C19: 46076 | D19: S/2026/1407/A | E19: F-04363 LUIGI DI PAOLO | G19: 46063 | H19: 2/FE | I19: 9204 | L19: =L18+I19-K19 -> 1481029.7
B20: Bill | C20: 46078 | D20: S/2026/1478/A | E20: F-03890 GIULIO FAZIO | G20: 46057 | H20: FPR 3/26 | I20: 8320 | L20: =L19+I20-K20 -> 1489349.7
B21: Bill | C21: 46078 | D21: S/2026/1480/A | E21: F-03890 GIULIO FAZIO | G21: 46057 | H21: FPR 2/26 | I21: 320 | L21: =L20+I21-K21 -> 1489669.7
B22: Bill Credit | C22: 46079 | D22: S/2026/1560/A | E22: F-03890 GIULIO FAZIO | G22: 46066 | H22: FPR 4/26 | K22: 8320 | L22: =L21+I22-K22 -> 1481349.7
B23: Bill | C23: 46079 | D23: S/2026/1550/A | E23: F-00348 TELESCA ROCCO DONATO | G23: 46078 | H23: FPR 5/26 | I23: 2080 | L23: =L22+I23-K23 -> 1483429.7
B24: Bill | C24: 46097 | D24: S/2026/2093/A | E24: F-03093 QUI ASSICURAZIONI S.R.L. | F24: %fornito | G24: 46097 | H24: AF01 383/26 | I24: 419.29 | L24: =L23+I24-K24 -> 1483848.9
B25: Bill | C25: 46097 | D25: S/2026/2089/A | E25: F-03890 GIULIO FAZIO | G25: 46085 | H25: FPR 5/26 | I25: 8320 | L25: =L24+I25-K25 -> 1492168.9
B26: Bill | C26: 46111 | D26: S/2026/2529/A | E26: F-00348 TELESCA ROCCO DONATO | G26: 46111 | H26: FPR 13/26 | I26: 2704 | L26: =L25+I26-K26 -> 1494872.9
B27: Bill | C27: 46114 | D27: S/2026/2613/A | E27: F-03093 QUI ASSICURAZIONI S.R.L. | G27: 46099 | H27: AF01 436/26 | I27: 104.82 | L27: =L26+I27-K27 -> 1494977.8
B28: Bill | C28: 46119 | D28: S/2026/2692/A | E28: F-03690 STEFANO CALIGARA | F28: Redazione del Progetto di Fattibilità Tecnico-Economica (PFTE)da presentare presso lAmministrazione Comunale di Gallarate (VA). VS incarico del 04.03.2026. Acconto. | G28: 46119 | H28: 29/E | I28: 17640 | J28: Costi di Progettazione | L28: =L27+I28-K28 -> 1512617.8
B29: Bill | C29: 46120 | D29: S/2026/2726/A | E29: F-01526 CARMINE VERLOTTA | F29: Indagine Geologica - Comune di Ruoti | G29: 46119 | H29: 3 | I29: 1500 | J29: 1.Spese di consulenza | L29: =L28+I29-K29 -> 1514117.8
B30: Bill | C30: 46122 | D30: S/2026/2797/A | E30: F-03890 GIULIO FAZIO | F30: consulenza contratto 2024 - servizi resi a marzo 2026 | G30: 46120 | H30: FPR 6/26 | I30: 8320 | J30: 1.Spese di consulenza | L30: =L29+I30-K30 -> 1522437.8
B31: Bill | C31: 46126 | D31: S/2026/3023/A | E31: F-01185 Antonio Venneri | F31: PROGETTAZIONE ESECUTIVA, COORDINAMENTO DELLA SICUREZZA IN FASE DI PROGETTAZIONE, DIREZIONE LAVORI E COORDINAMENTO DELLA SICUREZZA IN FASE DI ESECUZIONE- E.L.EN.A. CONTRATTO LOTTO 3 | G31: 46125 | H31: FPR 9/26 | I31: 125721.61 | J31: 1.Spese di consulenza | L31: =L30+I31-K31 -> 1648159.4
B32: Bill | C32: 46126 | D32: S/2026/3022/A | E32: F-01185 Antonio Venneri | F32: E.L.EN.A. CONTRATTO LOTTO 4 | G32: 46125 | H32: FPR 10/26 | I32: 71259.91 | J32: 1.Spese di consulenza | L32: =L31+I32-K32 -> 1719419.3
B33: Bill | C33: 46126 | D33: S/2026/3020/A | E33: F-01185 Antonio Venneri | F33: E.L.EN.A. CONTRATTO LOTTO 1 | G33: 46125 | H33: FPR 7/26 | I33: 190626.82 | J33: 1.Spese di consulenza | L33: =L32+I33-K33 -> 1910046.1
B34: Bill | C34: 46126 | D34: S/2026/3016/A | E34: F-01185 Antonio Venneri | F34: E.L.EN.A. CONTRATTO LOTTO 2 | G34: 46125 | H34: FPR 8/26 | I34: 164881.81 | J34: 1.Spese di consulenza | L34: =L33+I34-K34 -> 2074927.9
B35: Bill | C35: 46139 | D35: S/2026/3419/A | E35: F-00348 TELESCA ROCCO DONATO | G35: 46136 | H35: FPR 15/26 | I35: 2589.6 | L35: =L34+I35-K35 -> 2077517.5
B36: Bill | C36: 46140 | D36: S/2026/3460/A | E36: F-01623 Donato Miano | G36: 46137 | H36: FPR 30/26 | I36: 2080 | L36: =L35+I36-K36 -> 2079597.5
B37: Bill | C37: 46141 | D37: S/2026/3469/A | E37: F-04443 GMS ST.ASSOCIATO GUANELLA MONTANI SUSS | G37: 46119 | H37: 53/E | I37: 30680 | L37: =L36+I37-K37 -> 2110277.5
B38: Journal | C38: 46142 | D38: JE-CIV-22352 | I38: 5766.28 | L38: =L37+I38-K38 -> 2116043.8
B39: Bill | C39: 46154 | D39: S/2026/3862/A | E39: F-03890 GIULIO FAZIO | G39: 46154 | H39: FPR 9/26 | I39: 8606.83 | L39: =L38+I39-K39 -> 2124650.6
B40: Bill | C40: 46161 | D40: S/2026/4139/A | E40: F-02352 DE CHECCHI ANDREA | F40: Collaudo illuminazione pubblica Lanuvio | G40: 46160 | H40: FPR 2/26 | I40: 12480 | J40: 1.Spese di consulenza | L40: =L39+I40-K40 -> 2137130.6
B41: Bill | C41: 46167 | D41: S/2026/4275/A | E41: F-03093 QUI ASSICURAZIONI S.R.L. | F41: %fornito | G41: 46167 | H41: AF01 1078/26 | I41: 209.64 | L41: =L40+I41-K41 -> 2137340.3
B42: Bill | C42: 46167 | D42: S/2026/4274/A | E42: F-03093 QUI ASSICURAZIONI S.R.L. | F42: %fornito | G42: 46167 | H42: AF01 1076/26 | I42: 434.05 | L42: =L41+I42-K42 -> 2137774.3
...

Sheet 700409
A1: CiviSmart
A2: Parent Company : CiviSmart S.p.A.
A3: CIV| Schede Contabili
A4: 1 January 2026 - 31 August 2026
A7: Account | B7: Type | C7: Date | D7: Document Number | E7: Name | F7: Memo | G7: [IL] Reference Date | H7: [IL] Reference # | I7: Debit | J7: DESCRIZIONE | K7: NATURA DEL COSTO | L7: Credit | M7: Balance
A8: 70 - COSTI PER SERVIZI | M8: 0
A9: 7004 - Servizi Di Lavoro Parasub | M9: 0
A10: 700409 - Comp. Prof. Attinenti Attivita' | M10: 1091707.9
B11: Bill | C11: 46043 | D11: S/2026/0443/A | E11: F-00335 OMNIA FIDUCIARIA S.R.L. | F11: Si emette fattura per asseverazioni Piano Economico e Finanziario svolte per vs conto relative alle proposte di project finance presentate in partenariato con A2A ILLUMINAZIONE PUBBLICA SRL | G11: 46031 | H11: 25 | I11: 2800 | M11: 1094507.9
B12: Bill | C12: 46050 | D12: S/2026/0661/A | E12: F-00183 IMQ S.P.A. | F12: Oggetto: MANTENIMENTO 1° TRIMESTRE 2026 - CERTIFICATO 9191.STTR - NORMA ISO 14001 | G12: 46043 | H12: 226003611 | I12: 279.96 | M12: 1094787.8
B13: Bill | C13: 46050 | D13: S/2026/0662/A | E13: F-00183 IMQ S.P.A. | F13: Oggetto: MANTENIMENTO 1° TRIMESTRE 2026 - CERTIFICATO 9196.SLT1 - NORMA ISO 50001 | G13: 46043 | H13: 226003612 | I13: 286.98 | M13: 1095074.8
B14: Journal | C14: 46053 | D14: JE-CIV-18185 | E14: F-03748 CONSORZIO KREA SRL | F14: Avvallimento E.L.E.NA | I14: 37500 | M14: 1132574.8
B15: Journal | C15: 46053 | D15: JE-CIV-19070 | E15: F-04249 ATLANTICO S.p.A | I15: 10000 | M15: 1142574.8
B16: Journal | C16: 46053 | D16: JE-CIV-18184 | E16: F-03748 CONSORZIO KREA SRL | F16: Avvallimento E.L.E.NA | I16: 112500 | K16: 8.Altro | M16: 1255074.8
B17: Bill | C17: 46063 | D17: S/2026/0876/A | E17: F-00527 ARGENTA S.O.A. SPA | G17: 46059 | H17: 0000102 | I17: 1389.49 | M17: 1256464.3
B18: Bill | C18: 46078 | D18: S/2026/1533/A | E18: F-01831 TOTUM SRL | G18: 46078 | H18: FPR 3/26 | I18: 3500 | M18: 1259964.3
B19: Journal | C19: 46081 | D19: JE-CIV-19123 | E19: F-04249 ATLANTICO S.p.A | I19: 10200 | M19: 1270164.3
B20: Bill | C20: 46085 | D20: S/2026/1704/A | E20: F-00335 OMNIA FIDUCIARIA S.R.L. | F20: Si emette fattura per asseverazioni Piano Economico e Finanziario svolte per vs conto relative ai seguenti comuni: | G20: 46083 | H20: 5 | I20: 5600 | M20: 1275764.3
B21: Bill | C21: 46099 | D21: S/2026/2206/A | E21: F-00407 LABORATORIO ANALISI DI A. COVIELLO & C. S.A.S. | G21: 46091 | H21: 2026/10 | I21: 80 | M21: 1275844.3
B22: Bill | C22: 46099 | D22: S/2026/2226/A | E22: F-00247 QUALILAB S.R.L. | F22: RILIEVO FOTOMETRICO - 673-QL25 | G22: 46081 | H22: 183/2026 | I22: 9920 | K22: Verifiche qualità su lampade | M22: 1285764.3
B23: Bill | C23: 46100 | D23: S/2026/2305/A | E23: F-02168 ARCADIA 888 SRL | G23: 46091 | H23: 50 | I23: 1575 | M23: 1287339.3
B24: Bill | C24: 46106 | D24: S/2026/2409/A | E24: F-00183 IMQ S.P.A. | F24: Oggetto: VARIAZIONE CERTIFICATI PER LA NORMA ISO 14001 (CERTIFICATO 9191.STTR) | G24: 46104 | H24: 826007183 | I24: 50 | M24: 1287389.3
B25: Bill | C25: 46107 | D25: S/2026/2443/A | E25: F-01605 CREDITSAFE ITALIA SRL | G25: 46104 | H25: SID000236468 | I25: 800 | M25: 1288189.3
B26: Bill | C26: 46122 | D26: S/2026/2784/A | E26: F-00335 OMNIA FIDUCIARIA S.R.L. | F26: Si emette fattura per asseverazioni Piano Economico e Finanziario svolte per vs conto in partenariato con A2A ILLUMINAZIONE PUBBLICA SRL | G26: 46120 | H26: 11 | I26: 2100 | M26: 1290289.3
B27: Bill | C27: 46122 | D27: S/2026/2785/A | E27: F-00335 OMNIA FIDUCIARIA S.R.L. | F27: Si emette fattura per asseverazioni Piano Economico e Finanziario svolte per vs conto relative ai seguenti comuni: | G27: 46120 | H27: 12 | I27: 3900 | M27: 1294189.3
B28: Bill | C28: 46128 | D28: S/2026/3124/A | E28: F-00183 IMQ S.P.A. | F28: Oggetto: MANTENIMENTO 2° TRIMESTRE 2026 - CERTIFICATO 9196.SLT1 - NORMA ISO 50001 | G28: 46127 | H28: 226010856 | I28: 286.98 | M28: 1294476.3
B29: Bill | C29: 46128 | D29: S/2026/3123/A | E29: F-00183 IMQ S.P.A. | F29: Oggetto: MANTENIMENTO 2° TRIMESTRE 2026 - CERTIFICATO 9191.STTR - NORMA ISO 14001 | G29: 46127 | H29: 226010857 | I29: 279.96 | M29: 1294756.2
B30: Bill | C30: 46129 | D30: S/2026/3169/A | E30: F-04249 ATLANTICO S.p.A | F30: Servizi per indennizzo garanzie assicurative mese di marzo 2026 | G30: 46128 | H30: 000017 | I30: 10000 | M30: 1304756.2
B31: Bill | C31: 46134 | D31: S/2026/3270/A | E31: F-00183 IMQ S.P.A. | F31: Oggetto: RIESAME PRATICA PER RICERTIFICAZIONE PER LA NORMA ISO 14001 (CERTIFICATO 9191.STTR) | G31: 46132 | H31: 826009588 | I31: 200 | M31: 1304956.2
B32: Bill | C32: 46139 | D32: S/2026/3397/A | E32: F-01831 TOTUM SRL | F32: fattura per assistenza Vs sistemi aziendali (ISO 9001 - ISO 14001 - ISO 45001 - ISO 50001 - UNI CEI 11352 - PdR 125 e SA8000) | G32: 46136 | H32: FPR 5/26 | I32: 3500 | M32: 1308456.2
B33: Bill | C33: 46139 | D33: S/2026/3393/A | E33: F-02168 ARCADIA 888 SRL | F33: Asseverazione Piano Economico - Proposta PPP Riqualificazione energetica Comune di Saronno | G33: 46133 | H33: 75 | I33: 3150 | M33: 1311606.2
B34: Bill | C34: 46140 | D34: S/2026/3429/A | E34: F-01605 CREDITSAFE ITALIA SRL | F34: VISURA CAMERALE-DATABASE INTERNAZIONALE HOME-STANDARD PACK -Report Investigato Post-Affidamento-VISURA CAMERALE STORICA | G34: 46135 | H34: SID000242411 | I34: 800 | M34: 1312406.2
B35: Journal | C35: 46142 | D35: JE-CIV-22467 | E35: F-04476 VLN ENGINEERING SRL-F-04249 ATLANTICO S.p.A | F35: consulenza strategica gara SACILE-Servizi per indennizzo garanzie assicurative mese di aprile 2026 .- contratto IE59-26 preparazione busta tecnica gara SACILE (PN) | I35: 31250 | K35: 1.Spese di consulenza | M35: 1343656.2
B36: Bill | C36: 46155 | D36: S/2026/3913/A | E36: F-00335 OMNIA FIDUCIARIA S.R.L. | F36: Si emette fattura per asseverazioni Piano Economico e Finanziario svolte per vs conto relative ai seguenti comuni: | G36: 46154 | H36: 18 | I36: 2600 | M36: 1346256.2
B37: Bill | C37: 46157 | D37: S/2026/4070/A | E37: F-00183 IMQ S.P.A. | F37: Oggetto: RIESAME PRATICA PER RICERTIFICAZIONE PER LA NORMA ISO 45001 (CERTIFICATO 9192.STT3) | G37: 46155 | H37: 826011801 | I37: 200 | M37: 1346456.2
B38: Bill | C38: 46169 | D38: S/2026/4320/A | E38: F-01605 CREDITSAFE ITALIA SRL | G38: 46167 | H38: SID000247970 | I38: 800 | M38: 1347256.2
B39: Journal | C39: 46173 | D39: JE-CIV-23874 | I39: 5000 | M39: 1352256.2
B40: Bill | C40: 46176 | D40: S/2026/4440/A | E40: F-01831 TOTUM SRL | G40: 46174 | H40: FPR 7/26 | I40: 3500 | M40: 1355756.2
B41: Bill | C41: 46181 | D41: S/2026/4586/A | E41: F-00335 OMNIA FIDUCIARIA S.R.L. | F41: Si emette fattura per asseverazioni Piano Economico e Finanziario svolte per vs conto in partenariato con A2A ILLUMINAZIONE PUBBLICA SRL | G41: 46181 | H41: 22 | I41: 800 | M41: 1356556.2
B42: Bill | C42: 46181 | D42: S/2026/4589/A | E42: F-00335 OMNIA FIDUCIARIA S.R.L. | F42: Si emette fattura per asseverazioni Piano Economico e Finanziario svolte per vs conto relative ai seguenti comuni: | G42: 46181 | H42: 21 | I42: 2900 | M42: 1359456.2
...

Sheet 702001
A1: CiviSmart
A2: Parent Company : CiviSmart S.p.A.
A3: CIV| Schede Contabili
A4: 1 January 2026 - 31 August 2026
A7: Account | B7: Type | C7: Date | D7: Document Number | E7: Name | F7: Memo | G7: [IL] Reference Date | H7: [IL] Reference # | I7: Debit | J7: NATURA DEL COSTO | K7: Credit | L7: Balance
A8: 70 - COSTI PER SERVIZI | L8: 0
A9: 7020 - Spese Di Consulenza | L9: 0
A10: 702001 - Spese Di Consulenza | L10: 5735855.1
B11: Bill | C11: 46044 | D11: S/2026/0505/A | E11: F-03883 GIOVANNI RONDINA | G11: 46029 | H11: 1 | I11: 6000 | L11: =L10+I11-K11 -> 5741855.1
B12: Bill | C12: 46048 | D12: S/2026/0565/A | E12: F-04138 DI BUO' GIANLUCA | G12: 46046 | H12: 1 | I12: 3122 | L12: =L11+I12-K12 -> 5744977.1
B13: Bill | C13: 46048 | D13: S/2026/0568/A | E13: F-03802 DELOITTE AND TOUCHE S.p.A. | G13: 46045 | H13: 2630001291 | I13: 16200 | J13: Financial DD | L13: =L12+I13-K13 -> 5761177.1
B14: Bill | C14: 46048 | D14: S/2026/0571/A | E14: F-01831 TOTUM SRL | G14: 46045 | H14: FPR 1/26 | I14: 3500 | L14: =L13+I14-K14 -> 5764677.1
B15: Journal | C15: 46053 | D15: JE-CIV-18128 | I15: 2600 | L15: =L14+I15-K15 -> 5767277.1
B16: Journal | C16: 46053 | D16: JE-CIV-19987 | E16: F-01657 KPMG S.p.A. | I16: 25812 | J16: Attività pre-bid | L16: =L15+I16-K16 -> 5793089.1
B17: Journal | C17: 46053 | D17: JE-CIV-21018 | I17: 3400 | L17: =L16+I17-K17 -> 5796489.1
B18: Bill | C18: 46058 | D18: S/2026/0786/A | E18: F-03883 GIOVANNI RONDINA | G18: 46056 | H18: 2 | I18: 6000 | L18: =L17+I18-K18 -> 5802489.1
B19: Bill | C19: 46063 | D19: S/2026/0867/A | E19: F-04028 Marco La Diega s.r.l. | G19: 46049 | H19: 5 | I19: 900 | J19: Servizio DPO su Regolamento Privacy | L19: =L18+I19-K19 -> 5803389.1
B20: Bill | C20: 46063 | D20: S/2026/0862/A | E20: F-03645 DOMENICO MASTROLIA | G20: 46056 | H20: 7 | I20: 9360 | J20: 2.Assistenza Legale | L20: =L19+I20-K20 -> 5812749.1
B21: Bill | C21: 46078 | D21: S/2026/1456/A | E21: F-04138 DI BUO' GIANLUCA | G21: 46077 | H21: 2 | I21: 3122 | L21: =L20+I21-K21 -> 5815871.1
B22: Journal | C22: 46081 | D22: JE-CIV-19449 | E22: F-04354 GENERA INTEGRATED SOLUTIONS SRL | I22: 28500 | J22: Consulenza e Assistenza tecnica su Spezzano e Crosia | L22: =L21+I22-K22 -> 5844371.1
B23: Journal | C23: 46081 | D23: JE-CIV-19152 | I23: 223.8 | L23: =L22+I23-K23 -> 5844594.9
B24: Journal | C24: 46081 | D24: JE-CIV-19125 | I24: 3400 | L24: =L23+I24-K24 -> 5847994.9
B25: Journal | C25: 46081 | D25: JE-CIV-19160 | I25: 2600 | L25: =L24+I25-K25 -> 5850594.9
B26: Journal | C26: 46081 | D26: JE-CIV-23357 | I26: 5595 | L26: =L25+I26-K26 -> 5856189.9
B27: Bill | C27: 46083 | D27: S/2026/1647/A | E27: F-03642 AMAPOLA SRL SB | G27: 46080 | H27: 2600049 | I27: 8000 | L27: =L26+I27-K27 -> 5864189.9
B28: Bill | C28: 46084 | D28: S/2026/1683/A | E28: F-03949 FAVACCIO CORRADO | G28: 46083 | H28: FPR 1/26 | I28: 5200 | L28: =L27+I28-K28 -> 5869389.9
B29: Bill | C29: 46091 | D29: S/2026/1763/A | E29: F-01411 ATLANTE - CERASI Studio Notarile Associato | F29: Comunicazione di nomina (opzione 1 Crosia Smart City S.r.l.) rep. 73.288 racc. 37.963 in data 9 febbraio 2026, atto in autentica Notaio Nicola ATLANTE di Roma; successivi adempimenti: (*) registrazion e c/o l Agenzia delle Entrate du Roma 5 in data 10/2/2026; (*) rilascio di una copia autentica digitale per le parti in data 10/2/2026. | G29: 46087 | H29: 408 | I29: 801.05 | J29: 2.Assistenza Legale | L29: =L28+I29-K29 -> 5870190.9
B30: Bill | C30: 46091 | D30: S/2026/1765/A | E30: F-01411 ATLANTE - CERASI Studio Notarile Associato | F30: Comunicazione di nomina (opzione 2 Città Metropolitana di Venezia II Smart City S.r.l.) rep. 73.287 racc. 37.962 in data 9 febbraio 2026, atto in autentica Notaio Nicola ATLANTE di Roma; successivi ad empimenti: (*) registrazione c/o l Agenzia delle Entrate du Roma 5 in data 10/2/2026; (*) rilascio di una copia autentica digitale per le parti in data 10/2/2026. | G30: 46087 | H30: 407 | I30: 801.05 | J30: 2.Assistenza Legale | L30: =L29+I30-K30 -> 5870992
B31: Bill | C31: 46091 | D31: S/2026/1762/A | E31: F-01411 ATLANTE - CERASI Studio Notarile Associato | F31: Comunicazione di nomina (opzione 2 Crosia Smart City S.r.l.) rep. 73.289 racc. 37.964 in data 9 febbraio 2026, atto in autentica Notaio Nicola ATLANTE di Roma; successivi adempimenti: (*) registrazion e c/o l Agenzia delle Entrate du Roma 5 in data 10/2/2026; (*) rilascio di una copia autentica digitale per le parti in data 10/2/2026. | G31: 46087 | H31: 410 | I31: 801.05 | J31: 2.Assistenza Legale | L31: =L30+I31-K31 -> 5871793
B32: Bill | C32: 46091 | D32: S/2026/1764/A | E32: F-01411 ATLANTE - CERASI Studio Notarile Associato | F32: Comunicazione di nomina (opzione 1 società Spezzano Albanese Smart City S.r.l.) rep. 73.285 racc. 37.960 in data 9 febbraio 2026, atto in autentica Notaio Nicola ATLANTE di Roma; * COPIA DOCUMENTO in bollo (certificazione di conformità della procura a rogito Notaio Donatomarco Pirro di Roma del 5/2/2026 rep. 2936 racc.1744, contenuta su supporto informatico) rep. 73.283 in data 6/2/2026; successiv i adempimenti: (*) registrazione c/o l Agenzia delle Entrate du Roma 5 in data 10/2/2026; (*) rilascio di una copia autentica digitale per le parti in data 10/2/2026. | G32: 46087 | H32: 409 | I32: 824.71 | J32: 2.Assistenza Legale | L32: =L31+I32-K32 -> 5872617.7
B33: Bill | C33: 46091 | D33: S/2026/1766/A | E33: F-01411 ATLANTE - CERASI Studio Notarile Associato | F33: Comunicazione di nomina (opzione 1 Città Metropolitana di Venezia II Smart City S.r.l.) rep. 73.286 racc. 37.961 in data 9 febbraio 2026, atto in autentica Notaio Nicola ATLANTE di Roma; successivi ad empimenti: (*) registrazione c/o l Agenzia delle Entrate du Roma 5 in data 10/2/2026; (*) rilascio di una copia autentica digitale per le parti in data 10/2/2026. | G33: 46087 | H33: 406 | I33: 801.05 | J33: 2.Assistenza Legale | L33: =L32+I33-K33 -> 5873418.8
B34: Bill | C34: 46097 | D34: S/2026/2036/A | E34: F-01657 KPMG S.p.A. Revisione e organizzazione contabile | G34: 46080 | H34: 2026102156 | I34: 4320 | J34: Attività pre-bid | L34: =L33+I34-K34 -> 5877738.8
B35: Bill | C35: 46097 | D35: S/2026/2061/A | E35: F-03883 GIOVANNI RONDINA | G35: 46090 | H35: 3 | I35: 6000 | L35: =L34+I35-K35 -> 5883738.8
B36: Bill | C36: 46100 | D36: S/2026/2304/A | E36: F-04408 BELLEMO ERNANI | G36: 46094 | H36: 29 | I36: 2163 | L36: =L35+I36-K36 -> 5885901.8
B37: Bill | C37: 46100 | D37: S/2026/2309/A | E37: F-02464 EY ADVISORY S.P.A. | G37: 46085 | H37: IT03I3B2602108 | I37: 75900 | J37: Spese di consulenza | L37: =L36+I37-K37 -> 5961801.8
B38: Bill | C38: 46105 | D38: S/2026/2398/A | E38: F-03485 KPMG Advisory S.p.A | G38: 46101 | H38: 2026302126 | I38: 15000 | J38: Spese di consulenza | L38: =L37+I38-K38 -> 5976801.8
B39: Bill | C39: 46105 | D39: S/2026/2400/A | E39: F-03857 LEXIA | F39: Oggetto Project Sunset; fase 2 - acquisizione; compensi di cui alla lettera di incarico del 16 maggio 2025. | G39: 46100 | H39: 1099 | I39: 22880 | J39: Due Diligence | L39: =L38+I39-K39 -> 5999681.8
B40: Bill | C40: 46105 | D40: S/2026/2399/A | E40: F-04405 LEXIA AVVOCATI TRIBUTARIO E FINA NZA PUBBLICA | F40: Assistenza nella notifica Goldenpower relativa all acquisizione da parte di Civismart di societ� di Samsic. RGS 5480 | G40: 46099 | H40: 1/12 | I40: 7280 | J40: Due Diligence | L40: =L39+I40-K40 -> 6006961.8
B41: Bill | C41: 46106 | D41: S/2026/2420/A | E41: F-04423 STUDIO RSNOTAI | F41: Rep. 19563 del 10/03/2026 - Raggruppamento Temporaneo di Imprese Data operazione o incasso: 23/03/2026 | G41: 46104 | H41: 832 | I41: 1197.6 | J41: 2.Assistenza Legale | L41: =L40+I41-K41 -> 6008159.4
B42: Bill | C42: 46106 | D42: S/2026/2402/A | E42: F-04138 DI BUO' GIANLUCA | G42: 46105 | H42: 3 | I42: 3122 | L42: =L41+I42-K42 -> 6011281.4
...

Sheet 700815
A1: CiviSmart
A2: Parent Company : CiviSmart S.p.A.
A3: CIV| Schede Contabili
A4: 1 January 2026 - 31 August 2026
A7: Account | B7: Type | C7: Date | D7: Document Number | E7: Name | F7: Memo | G7: [IL] Reference Date | H7: [IL] Reference # | I7: Debit | J7: NATURA DEL COSTO | K7: Credit | L7: Balance
A8: 70 - COSTI PER SERVIZI | L8: 0
A9: 7008 - Spese Generali | L9: 0
A10: 700815 - Spese Per Trasferte | L10: 249262.19
B11: Journal | C11: 46023 | D11: JE-CIV-18652 | I11: 3 | L11: =L10+I11-K11 -> 249265.19
B12: Journal | C12: 46024 | D12: JE-CIV-18653 | I12: 9.5 | L12: =L11+I12-K12 -> 249274.69
B13: Journal | C13: 46024 | D13: JE-CIV-18654 | I13: 2.9 | L13: =L12+I13-K13 -> 249277.59
B14: Journal | C14: 46027 | D14: JE-CIV-18661 | I14: 20.8 | L14: =L13+I14-K14 -> 249298.39
B15: Journal | C15: 46029 | D15: JE-CIV-18460 | I15: 12 | L15: =L14+I15-K15 -> 249310.39
B16: Journal | C16: 46029 | D16: JE-CIV-18672 | I16: 42 | L16: =L15+I16-K16 -> 249352.39
B17: Journal | C17: 46029 | D17: JE-CIV-18337 | I17: 2 | L17: =L16+I17-K17 -> 249354.39
B18: Journal | C18: 46029 | D18: JE-CIV-18497 | I18: 6 | L18: =L17+I18-K18 -> 249360.39
B19: Journal | C19: 46030 | D19: JE-CIV-18499 | I19: 2.2 | L19: =L18+I19-K19 -> 249362.59
B20: Journal | C20: 46030 | D20: JE-CIV-18586 | I20: 13.9 | L20: =L19+I20-K20 -> 249376.49
B21: Journal | C21: 46030 | D21: JE-CIV-18461 | I21: 4.1 | L21: =L20+I21-K21 -> 249380.59
B22: Journal | C22: 46031 | D22: JE-CIV-18587 | I22: 16.5 | L22: =L21+I22-K22 -> 249397.09
... B49: Journal | C49: 46038 | D49: JE-CIV-18462 | I49: 4.9 | L49: =L48+I49-K49 -> 250216.07
B50: Journal | C50: 46038 | D50: JE-CIV-18525 | E50: Trenitalia SpA | I50: 899 | J50: Spese per trasferta | L50: =L49+I50-K50 -> 251115.07
B51: Journal | C51: 46039 | D51: JE-CIV-18691 | I51: 55 | L51: =L50+I51-K51 -> 251170.07
B52: Journal | C52: 46039 | D52: JE-CIV-18697 | I52: 143.11 | L52: =L51+I52-K52 -> 251313.18
B53: Journal | C53: 46040 | D53: JE-CIV-18702 | I53: 19.16 | L53: =L52+I53-K53 -> 251332.34
B54: Journal | C54: 46041 | D54: JE-CIV-18597 | I54: 20.6 | L54: =L53+I54-K54 -> 251352.94
B55: Journal | C55: 46041 | D55: JE-CIV-18501 | I55: 8 | L55: =L54+I55-K55 -> 251360.94
B56: Journal | C56: 46041 | D56: JE-CIV-18527 | I56: 18.1 | L56: =L55+I56-K56 -> 251379.04
B57: Journal | C57: 46041 | D57: JE-CIV-18591 | I57: 7 | L57: =L56+I57-K57 -> 251386.04
B58: Journal | C58: 46041 | D58: JE-CIV-18395 | I58: 6.46 | L58: =L57+I58-K58 -> 251392.5
B59: Journal | C59: 46041 | D59: JE-CIV-18529 | I59: 2.2 | L59: =L58+I59-K59 -> 251394.7
B60: Journal | C60: 46042 | D60: JE-CIV-18358 | I60: 32.26 | L60: =L59+I60-K60 -> 251426.96
B61: Journal | C61: 46042 | D61: JE-CIV-18502 | I61: 23.2 | L61: =L60+I61-K61 -> 251450.16
B62: Journal | C62: 46042 | D62: JE-CIV-18503 | I62: 4.4 | L62: =L61+I62-K62 -> 251454.56
... B67: Journal | C67: 46043 | D67: JE-CIV-18390 | I67: 9.66 | L67: =L66+I67-K67 -> 251511.32
B68: Bill | C68: 46043 | D68: S/2026/0433/A | E68: F-00093 Trenitalia S.p.A | G68: 46041 | H68: 2026/9000149832 | I68: 126 | L68: =L67+I68-K68 -> 251637.32
B69: Journal | C69: 46043 | D69: JE-CIV-18601 | I69: 40 | L69: =L68+I69-K69 -> 251677.32
B70: Bill | C70: 46043 | D70: S/2026/0437/A | E70: F-04313 J24HOTEL SRL | F70: Hotel J24 Lo Re | G70: 46036 | H70: 12600600J | I70: 112.19 | L70: =L69+I70-K70 -> 251789.51
B71: Journal | C71: 46043 | D71: JE-CIV-18504 | I71: 5.4 | L71: =L70+I71-K71 -> 251794.91
B72: Bill Credit | C72: 46043 | D72: S/2026/0422/A | E72: F-00093 Trenitalia S.p.A | G72: 46035 | H72: 2026/9000084602 | K72: 77 | L72: =L71+I72-K72 -> 251717.91
...
